Workbook

Sheet Index
C2: Оборотно-сальдовий баланс банку* | D2: відповідно до Додатку 1 до постанови Правління Національного банку України
D3: від 15 березня 2018 року № 11 "Про встановлення переліку інформації, що підлягає обов'язковому опублікуванню банками України" (зі змінами)
D4: за даними статистичної звітності з файлів 02X "Дані про обороти та залишки на рахунках".
A5: NKB | B5: Порядковий номер | C5: Назва банку | D5: Категорія банку | E5: МФО | F5: ПРОЦЕНТИ ЗА ДЕПОЗИТНИМИ СЕРТИФІКАТАМИ (ДС), тис. грн | G5: ПРОЦЕНТИ ЗА ОВДП (ОВДП), тис.грн | H5: ПРОЦЕНТИ ЗА КРЕДИТАМИ ЗДУ | I5: ПРОЦЕНТИ ЗА КРЕДИТАМИ БІЗНЕСУ | J5: ПРОЦЕНТИ ЗА КРЕДИТАМИ НАСЕЛЕННЮ | K5: ПРОЦЕНТНІ ДОХОДИ ВСЬОГО (ПД), тис. грн | L5: ДС/ПД, % | M5: ДС до підсумку, % | N5: (ДС+ОВДП)/ПД, % | O5: ОВДП/ПД, % | P5: ОВДП до підсумку | Q5: Обсяг ДС | R5: Кошти в НБУ (кор.рахунок) (кредит) (код 1200) | S5: Кошти в НБУ (УСЬОГО) (кредит) (розділ 12) | T5: Проценти за поточними вкладами ДГ (код 7040) | U5: Проценти за строковими вкладами ДГ (код 7041) | V5: Кредити субʼєктам господарювання (р.20, р.23, 260) | W5: Кредити ЗДУ (р.21) | X5: Кредити фізичним особам (р. 22, 24, 262) | Y5: Кредити небанківським установам (265) | Z5: Прибуток звітного року (5040) | AA5: Збиток звітного року (5041) | AB5: Податок на прибуток (7900) | AC5: Інші податки (741) | AD5: Відрахування в резерви (770) | AE5: Загальні доходи (6) | AF5: Загальні витрати (7)
A6: 2 | B6: 1 | C6: АТ "Укрексімбанк" | D6: Державний | E6: 322313 | F6: =' 2АТ "Укрексімбанк" '!O1130 | G6: =' 2АТ "Укрексімбанк" '!O1129 | H6: =' 2АТ "Укрексімбанк" '!O1140 | I6: =' 2АТ "Укрексімбанк" '!O1138 | J6: =' 2АТ "Укрексімбанк" '!O1139 | K6: =' 2АТ "Укрексімбанк" '!O1134 | L6: =IFERROR(F6/K6*100,0) | M6: =IFERROR(F6/SUM(F6:F11)*100,0) | N6: =IFERROR((F6+G6)/K6*100,0) | O6: =IFERROR(G6/K6*100,0) | P6: =IFERROR(G6/SUM(G6:G11)*100,0) | Q6: =' 2АТ "Укрексімбанк" '!O1131 | R6: =' 2АТ "Укрексімбанк" '!L1132 | S6: =' 2АТ "Укрексімбанк" '!L1133 | T6: =' 2АТ "Укрексімбанк" '!O1141 | U6: =' 2АТ "Укрексімбанк" '!O1142 | V6: =' 2АТ "Укрексімбанк" '!O1144 | W6: =' 2АТ "Укрексімбанк" '!O1145 | X6: =' 2АТ "Укрексімбанк" '!O1146 | Y6: =' 2АТ "Укрексімбанк" '!O1147 | Z6: =' 2АТ "Укрексімбанк" '!O1148 | AA6: =' 2АТ "Укрексімбанк" '!O1149 | AB6: =' 2АТ "Укрексімбанк" '!O1150 | AC6: =' 2АТ "Укрексімбанк" '!O1151 | AD6: =' 2АТ "Укрексімбанк" '!O1152 | AE6: =' 2АТ "Укрексімбанк" '!O1153 | AF6: =' 2АТ "Укрексімбанк" '!O1154
A7: 6 | B7: 2 | C7: АТ "Ощадбанк" | D7: Державний | E7: 300465 | F7: =' 6АТ "Ощадбанк" '!O1130 | G7: =' 6АТ "Ощадбанк" '!O1129 | H7: =' 6АТ "Ощадбанк" '!O1140 | I7: =' 6АТ "Ощадбанк" '!O1138 | J7: =' 6АТ "Ощадбанк" '!O1139 | K7: =' 6АТ "Ощадбанк" '!O1134 | L7: =IFERROR(F7/K7*100,0) | M7: =IFERROR(F7/SUM(F6:F11)*100,0) | N7: =IFERROR((F7+G7)/K7*100,0) | O7: =IFERROR(G7/K7*100,0) | P7: =IFERROR(G7/SUM(G6:G11)*100,0) | Q7: =' 6АТ "Ощадбанк" '!O1131 | R7: =' 6АТ "Ощадбанк" '!L1132 | S7: =' 6АТ "Ощадбанк" '!L1133 | T7: =' 6АТ "Ощадбанк" '!O1141 | U7: =' 6АТ "Ощадбанк" '!O1142 | V7: =' 6АТ "Ощадбанк" '!O1144 | W7: =' 6АТ "Ощадбанк" '!O1145 | X7: =' 6АТ "Ощадбанк" '!O1146 | Y7: =' 6АТ "Ощадбанк" '!O1147 | Z7: =' 6АТ "Ощадбанк" '!O1148 | AA7: =' 6АТ "Ощадбанк" '!O1149 | AB7: =' 6АТ "Ощадбанк" '!O1150 | AC7: =' 6АТ "Ощадбанк" '!O1151 | AD7: =' 6АТ "Ощадбанк" '!O1152 | AE7: =' 6АТ "Ощадбанк" '!O1153 | AF7: =' 6АТ "Ощадбанк" '!O1154
A8: 29 | B8: 3 | C8: АТ "БАНК АЛЬЯНС" | D8: Приватний капітал | E8: 300119 | F8: =' 29АТ "БАНК АЛЬЯНС" '!O1130 | G8: =' 29АТ "БАНК АЛЬЯНС" '!O1129 | H8: =' 29АТ "БАНК АЛЬЯНС" '!O1140 | I8: =' 29АТ "БАНК АЛЬЯНС" '!O1138 | J8: =' 29АТ "БАНК АЛЬЯНС" '!O1139 | K8: =' 29АТ "БАНК АЛЬЯНС" '!O1134 | L8: =IFERROR(F8/K8*100,0) | M8: =IFERROR(F8/SUM(F6:F11)*100,0) | N8: =IFERROR((F8+G8)/K8*100,0) | O8: =IFERROR(G8/K8*100,0) | P8: =IFERROR(G8/SUM(G6:G11)*100,0) | Q8: =' 29АТ "БАНК АЛЬЯНС" '!O1131 | R8: =' 29АТ "БАНК АЛЬЯНС" '!L1132 | S8: =' 29АТ "БАНК АЛЬЯНС" '!L1133 | T8: =' 29АТ "БАНК АЛЬЯНС" '!O1141 | U8: =' 29АТ "БАНК АЛЬЯНС" '!O1142 | V8: =' 29АТ "БАНК АЛЬЯНС" '!O1144 | W8: =' 29АТ "БАНК АЛЬЯНС" '!O1145 | X8: =' 29АТ "БАНК АЛЬЯНС" '!O1146 | Y8: =' 29АТ "БАНК АЛЬЯНС" '!O1147 | Z8: =' 29АТ "БАНК АЛЬЯНС" '!O1148 | AA8: =' 29АТ "БАНК АЛЬЯНС" '!O1149 | AB8: =' 29АТ "БАНК АЛЬЯНС" '!O1150 | AC8: =' 29АТ "БАНК АЛЬЯНС" '!O1151 | AD8: =' 29АТ "БАНК АЛЬЯНС" '!O1152 | AE8: =' 29АТ "БАНК АЛЬЯНС" '!O1153 | AF8: =' 29АТ "БАНК АЛЬЯНС" '!O1154
A9: 36 | B9: 4 | C9: АТ "Райффайзен Банк" | D9: Іноземний капітал | E9: 300335 | F9: =' 36АТ "Райффайзен Банк" '!O1130 | G9: =' 36АТ "Райффайзен Банк" '!O1129 | H9: =' 36АТ "Райффайзен Банк" '!O1140 | I9: =' 36АТ "Райффайзен Банк" '!O1138 | J9: =' 36АТ "Райффайзен Банк" '!O1139 | K9: =' 36АТ "Райффайзен Банк" '!O1134 | L9: =IFERROR(F9/K9*100,0) | M9: =IFERROR(F9/SUM(F6:F11)*100,0) | N9: =IFERROR((F9+G9)/K9*100,0) | O9: =IFERROR(G9/K9*100,0) | P9: =IFERROR(G9/SUM(G6:G11)*100,0) | Q9: =' 36АТ "Райффайзен Банк" '!O1131 | R9: =' 36АТ "Райффайзен Банк" '!L1132 | S9: =' 36АТ "Райффайзен Банк" '!L1133 | T9: =' 36АТ "Райффайзен Банк" '!O1141 | U9: =' 36АТ "Райффайзен Банк" '!O1142 | V9: =' 36АТ "Райффайзен Банк" '!O1144 | W9: =' 36АТ "Райффайзен Банк" '!O1145 | X9: =' 36АТ "Райффайзен Банк" '!O1146 | Y9: =' 36АТ "Райффайзен Банк" '!O1147 | Z9: =' 36АТ "Райффайзен Банк" '!O1148 | AA9: =' 36АТ "Райффайзен Банк" '!O1149 | AB9: =' 36АТ "Райффайзен Банк" '!O1150 | AC9: =' 36АТ "Райффайзен Банк" '!O1151 | AD9: =' 36АТ "Райффайзен Банк" '!O1152 | AE9: =' 36АТ "Райффайзен Банк" '!O1153 | AF9: =' 36АТ "Райффайзен Банк" '!O1154
A10: 43 | B10: 5 | C10: АТ "АЛЬТБАНК" | D10: Приватний капітал | E10: 320940 | F10: =' 43АТ "АЛЬТБАНК" '!O1130 | G10: =' 43АТ "АЛЬТБАНК" '!O1129 | H10: =' 43АТ "АЛЬТБАНК" '!O1140 | I10: =' 43АТ "АЛЬТБАНК" '!O1138 | J10: =' 43АТ "АЛЬТБАНК" '!O1139 | K10: =' 43АТ "АЛЬТБАНК" '!O1134 | L10: =IFERROR(F10/K10*100,0) | M10: =IFERROR(F10/SUM(F6:F11)*100,0) | N10: =IFERROR((F10+G10)/K10*100,0) | O10: =IFERROR(G10/K10*100,0) | P10: =IFERROR(G10/SUM(G6:G11)*100,0) | Q10: =' 43АТ "АЛЬТБАНК" '!O1131 | R10: =' 43АТ "АЛЬТБАНК" '!L1132 | S10: =' 43АТ "АЛЬТБАНК" '!L1133 | T10: =' 43АТ "АЛЬТБАНК" '!O1141 | U10: =' 43АТ "АЛЬТБАНК" '!O1142 | V10: =' 43АТ "АЛЬТБАНК" '!O1144 | W10: =' 43АТ "АЛЬТБАНК" '!O1145 | X10: =' 43АТ "АЛЬТБАНК" '!O1146 | Y10: =' 43АТ "АЛЬТБАНК" '!O1147 | Z10: =' 43АТ "АЛЬТБАНК" '!O1148 | AA10: =' 43АТ "АЛЬТБАНК" '!O1149 | AB10: =' 43АТ "АЛЬТБАНК" '!O1150 | AC10: =' 43АТ "АЛЬТБАНК" '!O1151 | AD10: =' 43АТ "АЛЬТБАНК" '!O1152 | AE10: =' 43АТ "АЛЬТБАНК" '!O1153 | AF10: =' 43АТ "АЛЬТБАНК" '!O1154
A11: 381 | B11: 6 | C11: АТ "МОТОР-БАНК"нпб | D11: Інше | E11: 313009 | F11: ='381АТ "МОТОР-БАНК"нпб'!O1130 | G11: ='381АТ "МОТОР-БАНК"нпб'!O1129 | H11: ='381АТ "МОТОР-БАНК"нпб'!O1140 | I11: ='381АТ "МОТОР-БАНК"нпб'!O1138 | J11: ='381АТ "МОТОР-БАНК"нпб'!O1139 | K11: ='381АТ "МОТОР-БАНК"нпб'!O1134 | L11: =IFERROR(F11/K11*100,0) | M11: =IFERROR(F11/SUM(F6:F11)*100,0) | N11: =IFERROR((F11+G11)/K11*100,0) | O11: =IFERROR(G11/K11*100,0) | P11: =IFERROR(G11/SUM(G6:G11)*100,0) | Q11: ='381АТ "МОТОР-БАНК"нпб'!O1131 | R11: ='381АТ "МОТОР-БАНК"нпб'!L1132 | S11: ='381АТ "МОТОР-БАНК"нпб'!L1133 | T11: ='381АТ "МОТОР-БАНК"нпб'!O1141 | U11: ='381АТ "МОТОР-БАНК"нпб'!O1142 | V11: ='381АТ "МОТОР-БАНК"нпб'!O1144 | W11: ='381АТ "МОТОР-БАНК"нпб'!O1145 | X11: ='381АТ "МОТОР-БАНК"нпб'!O1146 | Y11: ='381АТ "МОТОР-БАНК"нпб'!O1147 | Z11: ='381АТ "МОТОР-БАНК"нпб'!O1148 | AA11: ='381АТ "МОТОР-БАНК"нпб'!O1149 | AB11: ='381АТ "МОТОР-БАНК"нпб'!O1150 | AC11: ='381АТ "МОТОР-БАНК"нпб'!O1151 | AD11: ='381АТ "МОТОР-БАНК"нпб'!O1152 | AE11: ='381АТ "МОТОР-БАНК"нпб'!O1153 | AF11: ='381АТ "МОТОР-БАНК"нпб'!O1154
A12: Всього | F12: =IFERROR(SUM(F6:F11),0) | G12: =IFERROR(SUM(G6:G11),0) | H12: =IFERROR(SUM(H6:H11),0) | I12: =IFERROR(SUM(I6:I11),0) | J12: =IFERROR(SUM(J6:J11),0) | K12: =IFERROR(SUM(K6:K11),0) | L12: =IFERROR(F12/K12*100,0) | M12: =IFERROR(F12/SUM(F6:F11)*100,0) | N12: =IFERROR((F12+G12)/K12*100,0) | O12: =IFERROR(G12/K12*100,0) | P12: =IFERROR(G12/SUM(G6:G11)*100,0) | Q12: =IFERROR(SUM(Q6:Q11),0) | R12: =IFERROR(SUM(R6:R11),0) | S12: =IFERROR(SUM(S6:S11),0) | T12: =IFERROR(SUM(T6:T11),0) | U12: =IFERROR(SUM(U6:U11),0) | V12: =IFERROR(SUM(V6:V11),0) | W12: =IFERROR(SUM(W6:W11),0) | X12: =IFERROR(SUM(X6:X11),0) | ... AF12: =IFERROR(SUM(AF6:AF11),0)
A13: Державні банки | D13: 2 банк(и/ів) | F13: =IFERROR(SUM(F6,F7),0) | G13: =IFERROR(SUM(G6,G7),0) | H13: =IFERROR(SUM(H6,H7),0) | I13: =IFERROR(SUM(I6,I7),0) | J13: =IFERROR(SUM(J6,J7),0) | K13: =IFERROR(SUM(K6,K7),0) | L13: =IFERROR(F13/K13*100,0) | M13: =IFERROR(F13/F12*100,0) | N13: =IFERROR(SUM(N6,N7),0) | O13: =IFERROR(SUM(O6,O7),0) | P13: =IFERROR(G13/G12*100,0) | Q13: =IFERROR(SUM(Q6,Q7),0) | R13: =IFERROR(SUM(R6,R7),0) | S13: =IFERROR(SUM(S6,S7),0) | T13: =IFERROR(SUM(T6,T7),0) | U13: =IFERROR(SUM(U6,U7),0) | V13: =IFERROR(SUM(V6,V7),0) | W13: =IFERROR(SUM(W6,W7),0) | X13: =IFERROR(SUM(X6,X7),0) | ... AF13: =IFERROR(SUM(AF6,AF7),0)
A14: Банки з іноземним капіталом | D14: 1 банк(и/ів) | F14: =IFERROR(SUM(F9),0) | G14: =IFERROR(SUM(G9),0) | H14: =IFERROR(SUM(H9),0) | I14: =IFERROR(SUM(I9),0) | J14: =IFERROR(SUM(J9),0) | K14: =IFERROR(SUM(K9),0) | L14: =IFERROR(F14/K14*100,0) | M14: =IFERROR(F14/F12*100,0) | N14: =IFERROR(SUM(N9),0) | O14: =IFERROR(SUM(O9),0) | P14: =IFERROR(G14/G12*100,0) | Q14: =IFERROR(SUM(Q9),0) | R14: =IFERROR(SUM(R9),0) | S14: =IFERROR(SUM(S9),0) | T14: =IFERROR(SUM(T9),0) | U14: =IFERROR(SUM(U9),0) | V14: =IFERROR(SUM(V9),0) | W14: =IFERROR(SUM(W9),0) | X14: =IFERROR(SUM(X9),0) | ... AF14: =IFERROR(SUM(AF9),0)
A15: Банки з українським приватним капіталом | D15: 2 банк(и/ів) | F15: =IFERROR(SUM(F8,F10),0) | G15: =IFERROR(SUM(G8,G10),0) | H15: =IFERROR(SUM(H8,H10),0) | I15: =IFERROR(SUM(I8,I10),0) | J15: =IFERROR(SUM(J8,J10),0) | K15: =IFERROR(SUM(K8,K10),0) | L15: =IFERROR(F15/K15*100,0) | M15: =IFERROR(F15/F12*100,0) | N15: =IFERROR(SUM(N8,N10),0) | O15: =IFERROR(SUM(O8,O10),0) | P15: =IFERROR(G15/G12*100,0) | Q15: =IFERROR(SUM(Q8,Q10),0) | R15: =IFERROR(SUM(R8,R10),0) | S15: =IFERROR(SUM(S8,S10),0) | T15: =IFERROR(SUM(T8,T10),0) | U15: =IFERROR(SUM(U8,U10),0) | V15: =IFERROR(SUM(V8,V10),0) | W15: =IFERROR(SUM(W8,W10),0) | X15: =IFERROR(SUM(X8,X10),0) | ... AF15: =IFERROR(SUM(AF8,AF10),0)
A16: Інші банки | D16: 1 банк(и/ів) | F16: =IFERROR(SUM(F11),0) | G16: =IFERROR(SUM(G11),0) | H16: =IFERROR(SUM(H11),0) | I16: =IFERROR(SUM(I11),0) | J16: =IFERROR(SUM(J11),0) | K16: =IFERROR(SUM(K11),0) | L16: =IFERROR(F16/K16*100,0) | M16: =IFERROR(F16/F12*100,0) | N16: =IFERROR(SUM(N11),0) | O16: =IFERROR(SUM(O11),0) | P16: =IFERROR(G16/G12*100,0) | Q16: =IFERROR(SUM(Q11),0) | R16: =IFERROR(SUM(R11),0) | S16: =IFERROR(SUM(S11),0) | T16: =IFERROR(SUM(T11),0) | U16: =IFERROR(SUM(U11),0) | V16: =IFERROR(SUM(V11),0) | W16: =IFERROR(SUM(W11),0) | X16: =IFERROR(SUM(X11),0) | ... AF16: =IFERROR(SUM(AF11),0)
B18: Категорія | C18: ДС/ПД, % | H18: Категорія | I18: ДС до підсумку, %
B19: =A13 | C19: =IFERROR(L13,0) | H19: =A13 | I19: =IFERROR(M13,0)
B20: =A14 | C20: =IFERROR(L14,0) | H20: =A14 | I20: =IFERROR(M14,0)
B21: =A15 | C21: =IFERROR(L15,0) | H21: =A15 | I21: =IFERROR(M15,0)
B22: =A16 | C22: =IFERROR(L16,0) | H22: =A16 | I22: =IFERROR(M16,0)

Sheet Indicator_Summary
A1: ПРОЦЕНТНІ ДОХОДИ банків
B2: млрд | C2: %
A3: Депозитні сертифікати | B3: =SUM(Index!F6:F11)/1000000 | C3: =B3/B8 * 100
A4: ОВДП | B4: =SUM(Index!G6:G11)/1000000 | C4: =B4/B8 * 100
A5: Кредити бізнесу | B5: =SUM(Index!I6:I11)/1000000 | C5: =B5/B8 * 100
A6: Кредити населенню | B6: =SUM(Index!J6:J11)/1000000 | C6: =B6/B8 * 100
A7: Інші процентні доходи | B7: =B8 - (B3 +B4 +B5 +B6) | C7: =B7/B8 * 100
A8: ВСЬОГО | B8: =SUM(Index!K6:K11)/1000000 | C8: 100

Sheet Pivot_Data
A1: bank_code | B1: bank_name | C1: bank_class | D1: Kind | E1: indicator | F1: Class | G1: Division | H1: Group | I1: Balance | J1: Name | K1: Kind_Mark | L1: Debit_Total | M1: Debit_NC | N1: Debit_IC | O1: Credit_Total | P1: Credit_NC | Q1: Credit_IC | R1: Balance_Total | S1: Balance_NC | T1: Balance_IC
A2: 2 | B2: АТ "Укрексімбанк" | C2: державний | D2: Активи | E2: (без привʼязки) | F2: 1 | G2: 10 | H2: 100 | I2: 1001 | J2: Банкноти та монети в касі банку | K2: А | L2: 2232019.4 | M2: 1053099.1 | N2: 1178920.3 | O2: 2266548.1 | P2: 1055118 | Q2: 1211430.1 | R2: 803299.8 | S2: 221112.15 | T2: 582187.66
A3: 2 | B3: АТ "Укрексімбанк" | C3: державний | D3: Активи | E3: (без привʼязки) | F3: 1 | G3: 10 | H3: 100 | I3: 1002 | J3: Банкноти та монети в касі відділень банку | K3: А | L3: 92541.798 | M3: 42633.366 | N3: 49908.432 | O3: 91942.424 | P3: 40331.164 | Q3: 51611.26 | R3: 15163.933 | S3: 4553.7256 | T3: 10610.208
A4: 2 | B4: АТ "Укрексімбанк" | C4: державний | D4: Активи | E4: (без привʼязки) | F4: 1 | G4: 10 | H4: 100 | I4: 1004 | J4: Банкноти та монети в банкоматах | K4: А | L4: 1093212.5 | M4: 1093212.5 | N4: 0 | O4: 1127848.9 | P4: 1127848.9 | Q4: 0 | R4: 263889.59 | S4: 263889.59 | T4: 0
A5: 2 | B5: АТ "Укрексімбанк" | C5: державний | D5: Активи | E5: (без привʼязки) | F5: 1 | G5: 10 | H5: 100 | I5: 1005 | J5: Банкноти та монети, інкасовані до перерахування | K5: А | L5: 62532.715 | M5: 62532.715 | N5: 0 | O5: 62532.715 | P5: 62532.715 | Q5: 0 | R5: 0 | S5: 0 | T5: 0
A6: 2 | B6: АТ "Укрексімбанк" | C6: державний | D6: Активи | E6: (без привʼязки) | F6: 1 | G6: 10 | H6: 100 | I6: 1006 | J6: Банкноти та монети на зберіганні в інкасаторській компанії | K6: А | L6: 0 | M6: 0 | N6: 0 | O6: 0 | P6: 0 | Q6: 0 | R6: 0 | S6: 0 | T6: 0
A7: 2 | B7: АТ "Укрексімбанк" | C7: державний | D7: Активи | E7: (без привʼязки) | F7: 1 | G7: 10 | H7: 100 | I7: 1007 | J7: Банкноти та монети в дорозі | K7: А | L7: 572012.05 | M7: 168067.05 | N7: 403945 | O7: 516742.42 | P7: 158139.23 | Q7: 358603.18 | R7: 57529.923 | S7: 9927.8134 | T7: 47602.11
A8: 2 | B8: АТ "Укрексімбанк" | C8: державний | D8: Активи | E8: (без привʼязки) | F8: 1 | G8: 10 | H8: 101 | I8: 1011 | J8: Дорожні чеки в касі банку | K8: А | L8: 0 | M8: 0 | N8: 0 | O8: 0 | P8: 0 | Q8: 0 | R8: 0 | S8: 0 | T8: 0
A9: 2 | B9: АТ "Укрексімбанк" | C9: державний | D9: Активи | E9: (без привʼязки) | F9: 1 | G9: 10 | H9: 101 | I9: 1012 | J9: Дорожні чеки в касі відділень банку | K9: А | L9: 0 | M9: 0 | N9: 0 | O9: 0 | P9: 0 | Q9: 0 | R9: 0 | S9: 0 | T9: 0
A10: 2 | B10: АТ "Укрексімбанк" | C10: державний | D10: Активи | E10: (без привʼязки) | F10: 1 | G10: 10 | H10: 109 | I10: 1090 | J10: Резерви за готівковими коштами, наявність яких є непідтвердженою | K10: П | L10: 580.24613 | M10: 0 | N10: 580.24613 | O10: 862.24315 | P10: 0 | Q10: 862.24315 | R10: -52091.86 | S10: -5377.8999 | T10: -46713.96
A11: 2 | B11: АТ "Укрексімбанк" | C11: державний | D11: Активи | E11: (без привʼязки) | F11: 1 | G11: 11 | H11: 110 | I11: 1101 | J11: Банківські метали в банку | K11: А | L11: 0 | M11: 0 | N11: 0 | O11: 0 | P11: 0 | Q11: 0 | R11: 0 | S11: 0 | T11: 0
A12: 2 | B12: АТ "Укрексімбанк" | C12: державний | D12: Активи | E12: (без привʼязки) | F12: 1 | G12: 11 | H12: 110 | I12: 1102 | J12: Банківські метали у відділенні банку | K12: А | L12: 0 | M12: 0 | N12: 0 | O12: 0 | P12: 0 | Q12: 0 | R12: 0 | S12: 0 | T12: 0
A13: 2 | B13: АТ "Укрексімбанк" | C13: державний | D13: Активи | E13: (без привʼязки) | F13: 1 | G13: 11 | H13: 110 | I13: 1107 | J13: Банківські метали в дорозі | K13: А | L13: 0 | M13: 0 | N13: 0 | O13: 0 | P13: 0 | Q13: 0 | R13: 0 | S13: 0 | T13: 0
... A4699: 43 | B4699: АТ "АЛЬТБАНК" | C4699: приватний | D4699: Пасиви | E4699: (без привʼязки) | F4699: 9 | G4699: 99 | H4699: 992 | I4699: 9920 | J4699: Позабалансова позиція банку за іноземною валютою та банківськими металами | K4699: П | L4699: 0 | M4699: 0 | N4699: 0 | O4699: 0 | P4699: 0 | Q4699: 0 | R4699: 0 | S4699: 0 | T4699: 0

Sheet Зміст
B2: Оборотно-сальдовий баланс банку* | C2: відповідно до підпункту 1 пункту 2 постанови Правління Національного банку України
C3: від 15 березня 2018 року № 11 “Про встановлення переліку інформації, що підлягає обов'язковому опублікуванню банками України” (зі змінами)
C4: за даними статистичної звітності з файлу 02X “Дані про обороти та залишки на рахунках”.
A6: NKB | B6: Назва | C6: МФО
A7: 2 | B7: АТ "Укрексімбанк" | C7: 322313
A8: 6 | B8: АТ "ОЩАДБАНК" | C8: 300465
A9: 29 | B9: АТ "БАНК АЛЬЯНС" | C9: 300119
A10: 36 | B10: АТ "Райффайзен Банк" | C10: 300335
A11: 43 | B11: АТ "АЛЬТБАНК" | C11: 320940
A12: 46 | B12: АТ КБ "ПриватБанк" | C12: 305299
A13: 49 | B13: Полікомбанк | C13: 353100
A14: 62 | B14: АТ "ТАСКОМБАНК" | C14: 339500
A15: 72 | B15: ПрАТ "БАНК ФАМІЛЬНИЙ" | C15: 334840
A16: 88 | B16: АТ "КРЕДОБАНК" | C16: 325365
A17: 91 | B17: АТ АКБ "Львів" | C17: 325268
... A65: 694 | B65: АТ "КРИСТАЛБАНК" | C65: 339050
A66: 695 | B66: ПрАТ "ПЕРЕХІДНИЙ БАНК "ЮТЕ БАНК" | C66: 370140
A68: *Неплатоспроможні банки.

Sheet   2АТ "Укрексімбанк" 
A1: Зміст
B2: Оборотно-сальдовий баланс банку АТ "Укрексімбанк" за станом на 01.03.2026
B3: (тис грн)
A4: Номер з/п | B4: Клас/ розділ/ група/ рахунок | I4: Актив/ пасив | J4: Обороти за місяць | Q4: Сальдо
J5: дебет | M5: кредит | Q5: усього | R5: НВ | S5: ІВ
B6: номер | F6: назва | J6: усього | K6: НВ | L6: ІВ | M6: усього | O6: НВ | P6: ІВ
A7: 1 | B7: 2 | F7: 3 | I7: 4 | J7: 5 | K7: 6 | L7: 7 | M7: 8 | O7: 9 | P7: 10 | Q7: 11 | R7: 12 | S7: 13
A8: 1 | B8: Балансові рахунки
A9: 2 | B9: Активи
A10: 3 | B10: Класи 1 - 4
A11: 4 | B11: Клас 1 | C11: 10 | D11: 100 | F11: 1001 | H11: Банкноти та монети в касі банку | I11: А | J11: 2232019.4 | K11: 1053099.1 | L11: 1178920.3 | M11: 2266548.1 | O11: 1055118 | P11: 1211430.1 | Q11: 803299.8 | R11: 221112.15 | S11: 582187.66
A12: 5 | F12: 1002 | H12: Банкноти та монети в касі відділень банку | I12: А | J12: 92541.798 | K12: 42633.366 | L12: 49908.432 | M12: 91942.424 | O12: 40331.164 | P12: 51611.26 | Q12: 15163.933 | R12: 4553.7256 | S12: 10610.208
A13: 6 | F13: 1004 | H13: Банкноти та монети в банкоматах | I13: А | J13: 1093212.5 | K13: 1093212.5 | L13: 0 | M13: 1127848.9 | O13: 1127848.9 | P13: 0 | Q13: 263889.59 | R13: 263889.59 | S13: 0
A14: 7 | F14: 1005 | H14: Банкноти та монети, інкасовані до перерахування | I14: А | J14: 62532.715 | K14: 62532.715 | L14: 0 | M14: 62532.715 | O14: 62532.715 | P14: 0 | Q14: 0 | R14: 0 | S14: 0
A15: 8 | F15: 1006 | H15: Банкноти та монети на зберіганні в інкасаторській компанії | I15: А | J15: 0 | K15: 0 | L15: 0 | M15: 0 | O15: 0 | P15: 0 | Q15: 0 | R15: 0 | S15: 0
A16: 9 | F16: 1007 | H16: Банкноти та монети в дорозі | I16: А | J16: 572012.05 | K16: 168067.05 | L16: 403945 | M16: 516742.42 | O16: 158139.23 | P16: 358603.18 | Q16: 57529.923 | R16: 9927.8134 | S16: 47602.11
A17: 10 | F17: Група 100 - Усього | J17: 4052318.5 | K17: 2419544.8 | L17: 1632773.7 | M17: 4065614.5 | O17: 2443970 | P17: 1621644.6 | Q17: 1139883.3 | R17: 499483.28 | S17: 640399.97
A18: 11 | D18: 101 | F18: 1011 | H18: Дорожні чеки в касі банку | I18: А | J18: 0 | K18: 0 | L18: 0 | M18: 0 | O18: 0 | P18: 0 | Q18: 0 | R18: 0 | S18: 0
A19: 12 | F19: 1012 | H19: Дорожні чеки в касі відділень банку | I19: А | J19: 0 | K19: 0 | L19: 0 | M19: 0 | O19: 0 | P19: 0 | Q19: 0 | R19: 0 | S19: 0
A20: 13 | F20: Група 101 - Усього | J20: 0 | K20: 0 | L20: 0 | M20: 0 | O20: 0 | P20: 0 | Q20: 0 | R20: 0 | S20: 0
A21: 14 | D21: 109 | F21: 1090 | H21: Резерви за готівковими коштами, наявність яких є непідтвердженою | I21: П | J21: 580.24613 | K21: 0 | L21: 580.24613 | M21: 862.24315 | O21: 0 | P21: 862.24315 | Q21: -52091.86 | R21: -5377.8999 | S21: -46713.96
A22: 15 | F22: Група 109 - Усього | J22: 580.24613 | K22: 0 | L22: 580.24613 | M22: 862.24315 | O22: 0 | P22: 862.24315 | Q22: -52091.86 | R22: -5377.8999 | S22: -46713.96
A23: 16 | D23: Розділ 10 - Усього | J23: 4052898.7 | K23: 2419544.8 | L23: 1633354 | M23: 4066476.8 | O23: 2443970 | P23: 1622506.8 | Q23: 1087791.4 | R23: 494105.38 | S23: 593686.01
A24: 17 | C24: 11 | D24: 110 | F24: 1101 | H24: Банківські метали в банку | I24: А | J24: 0 | K24: 0 | L24: 0 | M24: 0 | O24: 0 | P24: 0 | Q24: 0 | R24: 0 | S24: 0
A25: 18 | F25: 1102 | H25: Банківські метали у відділенні банку | I25: А | J25: 0 | K25: 0 | L25: 0 | M25: 0 | O25: 0 | P25: 0 | Q25: 0 | R25: 0 | S25: 0
A26: 19 | F26: 1107 | H26: Банківські метали в дорозі | I26: А | J26: 0 | K26: 0 | L26: 0 | M26: 0 | O26: 0 | P26: 0 | Q26: 0 | R26: 0 | S26: 0
A27: 20 | F27: Група 110 - Усього | J27: 0 | K27: 0 | L27: 0 | M27: 0 | O27: 0 | P27: 0 | Q27: 0 | R27: 0 | S27: 0
A28: 21 | D28: 119 | F28: 1190 | H28: Резерви за банківськими металами, наявність яких є непідтвердженою | I28: П | J28: 0 | K28: 0 | L28: 0 | M28: 0 | O28: 0 | P28: 0 | Q28: 0 | R28: 0 | S28: 0
A29: 22 | F29: Група 119 - Усього | J29: 0 | K29: 0 | L29: 0 | M29: 0 | O29: 0 | P29: 0 | Q29: 0 | R29: 0 | S29: 0
A30: 23 | D30: Розділ 11 - Усього | J30: 0 | K30: 0 | L30: 0 | M30: 0 | O30: 0 | P30: 0 | Q30: 0 | R30: 0 | S30: 0
A31: 24 | C31: 12 | D31: 120 | F31: 1200 | H31: Кореспондентський рахунок банку в Національному банку України | I31: А | J31: 9.2610004e+08 | K31: 9.2610004e+08 | L31: 0 | M31: 9.4457766e+08 | O31: 9.4457766e+08 | P31: 0 | Q31: 22264737 | R31: 22264737 | S31: 0
A32: 25 | F32: 1202 | H32: Кошти банків за рахунками умовного зберігання (ескроу) у Національному банку України | I32: А | J32: 0 | K32: 0 | L32: 0 | M32: 0 | O32: 0 | P32: 0 | Q32: 0 | R32: 0 | S32: 0
A33: 26 | F33: 1205 | H33: Кошти банків для забезпечення виконання зобов’язань перед Національним банком України за кредитами, наданими банкам, та операціями своп процентної ставки | I33: А | J33: 0 | K33: 0 | L33: 0 | M33: 0 | O33: 0 | P33: 0 | Q33: 0 | R33: 0 | S33: 0
A34: 27 | F34: 1208 | H34: Нараховані доходи за коштами на вимогу в Національному банку України | I34: А | J34: 0 | K34: 0 | L34: 0 | M34: 0 | O34: 0 | P34: 0 | Q34: 0 | R34: 0 | S34: 0
A35: 28 | F35: Група 120 - Усього | J35: 9.2610004e+08 | K35: 9.2610004e+08 | L35: 0 | M35: 9.4457766e+08 | O35: 9.4457766e+08 | P35: 0 | Q35: 22264737 | R35: 22264737 | S35: 0
A36: 29 | D36: Розділ 12 - Усього | J36: 9.2610004e+08 | K36: 9.2610004e+08 | L36: 0 | M36: 9.4457766e+08 | O36: 9.4457766e+08 | P36: 0 | Q36: 22264737 | R36: 22264737 | S36: 0
A37: 30 | C37: 14 | D37: 140 | F37: 1400 | H37: Облігації внутрішньої державної позики, що рефінансуються Національним банком України, які обліковуються за справедливою вартістю через прибутки/збитки | I37: А | J37: 14123037 | K37: 12375430 | L37: 1747606.7 | M37: 15507637 | O37: 13864351 | P37: 1643286.4 | Q37: 7224374.4 | R37: 7001935 | S37: 222439.43
A38: 31 | F38: 1405 | H38: Переоцінка боргових цінних паперів, що рефінансуються Національним банком України, які обліковуються за справедливою вартістю через прибутки/збитки | I38: А | J38: 268455.54 | K38: 267186.83 | L38: 1268.7109 | M38: 184814.09 | O38: 182117.37 | P38: 2696.7177 | Q38: 1171947 | R38: 1171814.2 | S38: 132.77157
A39: 32 | I39: П | J39: 0 | K39: 0 | L39: 0 | M39: 0 | O39: 0 | P39: 0 | Q39: -11150.005 | R39: -10297.678 | S39: -852.3269
A40: 33 | F40: 1406 | H40: Неамортизована премія/дисконт за борговими цінними паперами, що рефінансуються Національним банком України, які обліковуються за справедливою вартістю через прибутки/збитки | I40: А | J40: 157462.82 | K40: 139797.01 | L40: 17665.815 | M40: 177508.8 | O40: 161428.53 | P40: 16080.273 | Q40: 673032.14 | R40: 670533.72 | S40: 2498.4182
...

Sheet   6АТ "Ощадбанк" 
A1: Зміст
B2: Оборотно-сальдовий баланс банку АТ "Ощадбанк" за станом на 01.03.2026
B3: (тис грн)
A4: Номер з/п | B4: Клас/ розділ/ група/ рахунок | I4: Актив/ пасив | J4: Обороти за місяць | Q4: Сальдо
J5: дебет | M5: кредит | Q5: усього | R5: НВ | S5: ІВ
B6: номер | F6: назва | J6: усього | K6: НВ | L6: ІВ | M6: усього | O6: НВ | P6: ІВ
A7: 1 | B7: 2 | F7: 3 | I7: 4 | J7: 5 | K7: 6 | L7: 7 | M7: 8 | O7: 9 | P7: 10 | Q7: 11 | R7: 12 | S7: 13
A8: 1 | B8: Балансові рахунки
A9: 2 | B9: Активи
A10: 3 | B10: Класи 1 - 4
A11: 4 | B11: Клас 1 | C11: 10 | D11: 100 | F11: 1001 | H11: Банкноти та монети в касі банку | I11: А | J11: 3.2940591e+08 | K11: 2.4121788e+08 | L11: 88188034 | M11: 3.2858763e+08 | O11: 2.4112026e+08 | P11: 87467365 | Q11: 13348535 | R11: 4567955.7 | S11: 8780579.2
A12: 5 | F12: 1002 | H12: Банкноти та монети в касі відділень банку | I12: А | J12: 28078075 | K12: 19342710 | L12: 8735365.4 | M12: 28234772 | O12: 19484727 | P12: 8750044.1 | Q12: 1501348.2 | R12: 936716.74 | S12: 564631.42
A13: 6 | F13: 1004 | H13: Банкноти та монети в банкоматах | I13: А | J13: 25813113 | K13: 25813113 | L13: 0 | M13: 26185548 | O13: 26185548 | P13: 0 | Q13: 3350937 | R13: 3350937 | S13: 0
A14: 7 | F14: 1005 | H14: Банкноти та монети, інкасовані до перерахування | I14: А | J14: 40976222 | K14: 40976222 | L14: 0 | M14: 40976222 | O14: 40976222 | P14: 0 | Q14: 0 | R14: 0 | S14: 0
A15: 8 | F15: 1006 | H15: Банкноти та монети на зберіганні в інкасаторській компанії | I15: А | J15: 0 | K15: 0 | L15: 0 | M15: 0 | O15: 0 | P15: 0 | Q15: 0 | R15: 0 | S15: 0
A16: 9 | F16: 1007 | H16: Банкноти та монети в дорозі | I16: А | J16: 1.312748e+08 | K16: 94542321 | L16: 36732483 | M16: 1.3130096e+08 | O16: 94553465 | P16: 36747492 | Q16: 124612.51 | R16: 87996.62 | S16: 36615.886
A17: 10 | F17: Група 100 - Усього | J17: 5.5554813e+08 | K17: 4.2189224e+08 | L17: 1.3365588e+08 | M17: 5.5528512e+08 | O17: 4.2232022e+08 | P17: 1.329649e+08 | Q17: 18325433 | R17: 8943606 | S17: 9381826.5
A18: 11 | D18: 101 | F18: 1011 | H18: Дорожні чеки в касі банку | I18: А | J18: 0 | K18: 0 | L18: 0 | M18: 0 | O18: 0 | P18: 0 | Q18: 0 | R18: 0 | S18: 0
A19: 12 | F19: 1012 | H19: Дорожні чеки в касі відділень банку | I19: А | J19: 0 | K19: 0 | L19: 0 | M19: 0 | O19: 0 | P19: 0 | Q19: 0 | R19: 0 | S19: 0
A20: 13 | F20: Група 101 - Усього | J20: 0 | K20: 0 | L20: 0 | M20: 0 | O20: 0 | P20: 0 | Q20: 0 | R20: 0 | S20: 0
A21: 14 | D21: 109 | F21: 1090 | H21: Резерви за готівковими коштами, наявність яких є непідтвердженою | I21: П | J21: 248.44174 | K21: 0 | L21: 248.44174 | M21: 399.74697 | O21: 0 | P21: 399.74697 | Q21: -95568.364 | R21: -73346.687 | S21: -22221.676
A22: 15 | F22: Група 109 - Усього | J22: 248.44174 | K22: 0 | L22: 248.44174 | M22: 399.74697 | O22: 0 | P22: 399.74697 | Q22: -95568.364 | R22: -73346.687 | S22: -22221.676
A23: 16 | D23: Розділ 10 - Усього | J23: 5.5554837e+08 | K23: 4.2189224e+08 | L23: 1.3365613e+08 | M23: 5.5528552e+08 | O23: 4.2232022e+08 | P23: 1.329653e+08 | Q23: 18229864 | R23: 8870259.3 | S23: 9359604.8
A24: 17 | C24: 11 | D24: 110 | F24: 1101 | H24: Банківські метали в банку | I24: А | J24: 1344160.1 | K24: 0 | L24: 1344160.1 | M24: 1367621.5 | O24: 0 | P24: 1367621.5 | Q24: 72233.49 | R24: 0 | S24: 72233.49
A25: 18 | F25: 1102 | H25: Банківські метали у відділенні банку | I25: А | J25: 14442.208 | K25: 0 | L25: 14442.208 | M25: 18122.768 | O25: 0 | P25: 18122.768 | Q25: 25530.823 | R25: 0 | S25: 25530.823
A26: 19 | F26: 1107 | H26: Банківські метали в дорозі | I26: А | J26: 20398.936 | K26: 0 | L26: 20398.936 | M26: 20403.005 | O26: 0 | P26: 20403.005 | Q26: 0 | R26: 0 | S26: 0
A27: 20 | F27: Група 110 - Усього | J27: 1379001.3 | K27: 0 | L27: 1379001.3 | M27: 1406147.3 | O27: 0 | P27: 1406147.3 | Q27: 97764.313 | R27: 0 | S27: 97764.313
A28: 21 | D28: 119 | F28: 1190 | H28: Резерви за банківськими металами, наявність яких є непідтвердженою | I28: П | J28: 764.16045 | K28: 0 | L28: 764.16045 | M28: 459.96969 | O28: 0 | P28: 459.96969 | Q28: -2081.7807 | R28: 0 | S28: -2081.7807
A29: 22 | F29: Група 119 - Усього | J29: 764.16045 | K29: 0 | L29: 764.16045 | M29: 459.96969 | O29: 0 | P29: 459.96969 | Q29: -2081.7807 | R29: 0 | S29: -2081.7807
A30: 23 | D30: Розділ 11 - Усього | J30: 1379765.4 | K30: 0 | L30: 1379765.4 | M30: 1406607.2 | O30: 0 | P30: 1406607.2 | Q30: 95682.533 | R30: 0 | S30: 95682.533
A31: 24 | C31: 12 | D31: 120 | F31: 1200 | H31: Кореспондентський рахунок банку в Національному банку України | I31: А | J31: 1.4126544e+09 | K31: 1.4126544e+09 | L31: 0 | M31: 1.4078833e+09 | O31: 1.4078833e+09 | P31: 0 | Q31: 35005070 | R31: 35005070 | S31: 0
A32: 25 | F32: 1202 | H32: Кошти банків за рахунками умовного зберігання (ескроу) у Національному банку України | I32: А | J32: 5604.5031 | K32: 0 | L32: 5604.5031 | M32: 3004.9153 | O32: 0 | P32: 3004.9153 | Q32: 320829.45 | R32: 8647 | S32: 312182.45
A33: 26 | F33: 1205 | H33: Кошти банків для забезпечення виконання зобов’язань перед Національним банком України за кредитами, наданими банкам, та операціями своп процентної ставки | I33: А | J33: 0 | K33: 0 | L33: 0 | M33: 0 | O33: 0 | P33: 0 | Q33: 0 | R33: 0 | S33: 0
A34: 27 | F34: 1208 | H34: Нараховані доходи за коштами на вимогу в Національному банку України | I34: А | J34: 668.44388 | K34: 0 | L34: 668.44388 | M34: 668.44388 | O34: 0 | P34: 668.44388 | Q34: 0 | R34: 0 | S34: 0
A35: 28 | F35: Група 120 - Усього | J35: 1.4126607e+09 | K35: 1.4126544e+09 | L35: 6272.947 | M35: 1.407887e+09 | O35: 1.4078833e+09 | P35: 3673.3592 | Q35: 35325899 | R35: 35013717 | S35: 312182.45
A36: 29 | D36: Розділ 12 - Усього | J36: 1.4126607e+09 | K36: 1.4126544e+09 | L36: 6272.947 | M36: 1.407887e+09 | O36: 1.4078833e+09 | P36: 3673.3592 | Q36: 35325899 | R36: 35013717 | S36: 312182.45
A37: 30 | C37: 14 | D37: 140 | F37: 1400 | H37: Облігації внутрішньої державної позики, що рефінансуються Національним банком України, які обліковуються за справедливою вартістю через прибутки/збитки | I37: А | J37: 136125.11 | K37: 115432 | L37: 20693.113 | M37: 160322.98 | O37: 151441 | P37: 8881.9818 | Q37: 9483961.9 | R37: 9305662 | S37: 178299.93
A38: 31 | F38: 1405 | H38: Переоцінка боргових цінних паперів, що рефінансуються Національним банком України, які обліковуються за справедливою вартістю через прибутки/збитки | I38: А | J38: 19838922 | K38: 19817776 | L38: 21145.536 | M38: 19633143 | O38: 19612606 | P38: 20536.424 | Q38: 6574794.9 | R38: 6573515.7 | S38: 1279.2501
A39: 32 | I39: П | J39: 0 | K39: 0 | L39: 0 | M39: 0 | O39: 0 | P39: 0 | Q39: -863801.83 | R39: -863801.83 | S39: 0
A40: 33 | F40: 1406 | H40: Неамортизована премія/дисконт за борговими цінними паперами, що рефінансуються Національним банком України, які обліковуються за справедливою вартістю через прибутки/збитки | I40: А | J40: 21421.294 | K40: 21377.283 | L40: 44.01095 | M40: 195.46714 | O40: 184.94964 | P40: 10.5175 | Q40: 323.43646 | R40: 290.8407 | S40: 32.59576
...

Sheet 381АТ "МОТОР-БАНК"нпб
A1: Зміст
B2: Оборотно-сальдовий баланс банку АТ "МОТОР-БАНК" за станом на 01.03.2026
B3: (тис грн)
A4: Номер з/п | B4: Клас/ розділ/ група/ рахунок | I4: Актив/ пасив | J4: Обороти за місяць | Q4: Сальдо
J5: дебет | M5: кредит | Q5: усього | R5: НВ | S5: ІВ
B6: номер | F6: назва | J6: усього | K6: НВ | L6: ІВ | M6: усього | O6: НВ | P6: ІВ
A7: 1 | B7: 2 | F7: 3 | I7: 4 | J7: 5 | K7: 6 | L7: 7 | M7: 8 | O7: 9 | P7: 10 | Q7: 11 | R7: 12 | S7: 13
A8: 1 | B8: Балансові рахунки
A9: 2 | B9: Активи
A10: 3 | B10: Класи 1 - 4
A11: 4 | B11: Клас 1 | C11: 10 | D11: 100 | F11: 1001 | H11: Банкноти та монети в касі банку | I11: А | J11: 0 | K11: 0 | L11: 0 | M11: 0 | O11: 0 | P11: 0 | Q11: 0 | R11: 0 | S11: 0
A12: 5 | F12: 1002 | H12: Банкноти та монети в касі відділень банку | I12: А | J12: 125455.89 | K12: 81460.106 | L12: 43995.781 | M12: 144808.97 | O12: 100864.57 | P12: 43944.402 | Q12: 13148.155 | R12: 4251.542 | S12: 8896.613
A13: 6 | F13: 1004 | H13: Банкноти та монети в банкоматах | I13: А | J13: 5940 | K13: 5940 | L13: 0 | M13: 10685 | O13: 10685 | P13: 0 | Q13: 0 | R13: 0 | S13: 0
A14: 7 | F14: 1005 | H14: Банкноти та монети, інкасовані до перерахування | I14: А | J14: 0 | K14: 0 | L14: 0 | M14: 0 | O14: 0 | P14: 0 | Q14: 0 | R14: 0 | S14: 0
A15: 8 | F15: 1006 | H15: Банкноти та монети на зберіганні в інкасаторській компанії | I15: А | J15: 0 | K15: 0 | L15: 0 | M15: 0 | O15: 0 | P15: 0 | Q15: 0 | R15: 0 | S15: 0
A16: 9 | F16: 1007 | H16: Банкноти та монети в дорозі | I16: А | J16: 17380 | K16: 17380 | L16: 0 | M16: 17380 | O16: 17380 | P16: 0 | Q16: 0 | R16: 0 | S16: 0
A17: 10 | F17: Група 100 - Усього | J17: 148775.89 | K17: 104780.11 | L17: 43995.781 | M17: 172873.97 | O17: 128929.57 | P17: 43944.402 | Q17: 13148.155 | R17: 4251.542 | S17: 8896.613
A18: 11 | D18: 101 | F18: 1011 | H18: Дорожні чеки в касі банку | I18: А | J18: 0 | K18: 0 | L18: 0 | M18: 0 | O18: 0 | P18: 0 | Q18: 0 | R18: 0 | S18: 0
A19: 12 | F19: 1012 | H19: Дорожні чеки в касі відділень банку | I19: А | J19: 0 | K19: 0 | L19: 0 | M19: 0 | O19: 0 | P19: 0 | Q19: 0 | R19: 0 | S19: 0
A20: 13 | F20: Група 101 - Усього | J20: 0 | K20: 0 | L20: 0 | M20: 0 | O20: 0 | P20: 0 | Q20: 0 | R20: 0 | S20: 0
A21: 14 | D21: 109 | F21: 1090 | H21: Резерви за готівковими коштами, наявність яких є непідтвердженою | I21: П | J21: 0 | K21: 0 | L21: 0 | M21: 0 | O21: 0 | P21: 0 | Q21: 0 | R21: 0 | S21: 0
A22: 15 | F22: Група 109 - Усього | J22: 0 | K22: 0 | L22: 0 | M22: 0 | O22: 0 | P22: 0 | Q22: 0 | R22: 0 | S22: 0
A23: 16 | D23: Розділ 10 - Усього | J23: 148775.89 | K23: 104780.11 | L23: 43995.781 | M23: 172873.97 | O23: 128929.57 | P23: 43944.402 | Q23: 13148.155 | R23: 4251.542 | S23: 8896.613
A24: 17 | C24: 11 | D24: 110 | F24: 1101 | H24: Банківські метали в банку | I24: А | J24: 0 | K24: 0 | L24: 0 | M24: 0 | O24: 0 | P24: 0 | Q24: 0 | R24: 0 | S24: 0
A25: 18 | F25: 1102 | H25: Банківські метали у відділенні банку | I25: А | J25: 57.73313 | K25: 0 | L25: 57.73313 | M25: 80.07966 | O25: 0 | P25: 80.07966 | Q25: 376.10419 | R25: 0 | S25: 376.10419
A26: 19 | F26: 1107 | H26: Банківські метали в дорозі | I26: А | J26: 0 | K26: 0 | L26: 0 | M26: 0 | O26: 0 | P26: 0 | Q26: 0 | R26: 0 | S26: 0
A27: 20 | F27: Група 110 - Усього | J27: 57.73313 | K27: 0 | L27: 57.73313 | M27: 80.07966 | O27: 0 | P27: 80.07966 | Q27: 376.10419 | R27: 0 | S27: 376.10419
A28: 21 | D28: 119 | F28: 1190 | H28: Резерви за банківськими металами, наявність яких є непідтвердженою | I28: П | J28: 0 | K28: 0 | L28: 0 | M28: 0 | O28: 0 | P28: 0 | Q28: 0 | R28: 0 | S28: 0
A29: 22 | F29: Група 119 - Усього | J29: 0 | K29: 0 | L29: 0 | M29: 0 | O29: 0 | P29: 0 | Q29: 0 | R29: 0 | S29: 0
A30: 23 | D30: Розділ 11 - Усього | J30: 57.73313 | K30: 0 | L30: 57.73313 | M30: 80.07966 | O30: 0 | P30: 80.07966 | Q30: 376.10419 | R30: 0 | S30: 376.10419
A31: 24 | C31: 12 | D31: 120 | F31: 1200 | H31: Кореспондентський рахунок банку в Національному банку України | I31: А | J31: 3270062 | K31: 3270062 | L31: 0 | M31: 3061660 | O31: 3061660 | P31: 0 | Q31: 227747.51 | R31: 227747.51 | S31: 0
A32: 25 | F32: 1202 | H32: Кошти банків за рахунками умовного зберігання (ескроу) у Національному банку України | I32: А | J32: 0 | K32: 0 | L32: 0 | M32: 0 | O32: 0 | P32: 0 | Q32: 0 | R32: 0 | S32: 0
A33: 26 | F33: 1205 | H33: Кошти банків для забезпечення виконання зобов’язань перед Національним банком України за кредитами, наданими банкам, та операціями своп процентної ставки | I33: А | J33: 0 | K33: 0 | L33: 0 | M33: 0 | O33: 0 | P33: 0 | Q33: 0 | R33: 0 | S33: 0
A34: 27 | F34: 1208 | H34: Нараховані доходи за коштами на вимогу в Національному банку України | I34: А | J34: 0 | K34: 0 | L34: 0 | M34: 0 | O34: 0 | P34: 0 | Q34: 0 | R34: 0 | S34: 0
A35: 28 | F35: Група 120 - Усього | J35: 3270062 | K35: 3270062 | L35: 0 | M35: 3061660 | O35: 3061660 | P35: 0 | Q35: 227747.51 | R35: 227747.51 | S35: 0
A36: 29 | D36: Розділ 12 - Усього | J36: 3270062 | K36: 3270062 | L36: 0 | M36: 3061660 | O36: 3061660 | P36: 0 | Q36: 227747.51 | R36: 227747.51 | S36: 0
A37: 30 | C37: 14 | D37: 140 | F37: 1400 | H37: Облігації внутрішньої державної позики, що рефінансуються Національним банком України, які обліковуються за справедливою вартістю через прибутки/збитки | I37: А | J37: 0 | K37: 0 | L37: 0 | M37: 0 | O37: 0 | P37: 0 | Q37: 0 | R37: 0 | S37: 0
A38: 31 | F38: 1405 | H38: Переоцінка боргових цінних паперів, що рефінансуються Національним банком України, які обліковуються за справедливою вартістю через прибутки/збитки | I38: А | J38: 0 | K38: 0 | L38: 0 | M38: 0 | O38: 0 | P38: 0 | Q38: 0 | R38: 0 | S38: 0
A39: 32 | I39: П | J39: 0 | K39: 0 | L39: 0 | M39: 0 | O39: 0 | P39: 0 | Q39: 0 | R39: 0 | S39: 0
A40: 33 | F40: 1406 | H40: Неамортизована премія/дисконт за борговими цінними паперами, що рефінансуються Національним банком України, які обліковуються за справедливою вартістю через прибутки/збитки | I40: А | J40: 0 | K40: 0 | L40: 0 | M40: 0 | O40: 0 | P40: 0 | Q40: 0 | R40: 0 | S40: 0
...

Sheet  29АТ "БАНК АЛЬЯНС" 
A1: Зміст
B2: Оборотно-сальдовий баланс банку АТ "БАНК АЛЬЯНС" за станом на 01.03.2026
B3: (тис грн)
A4: Номер з/п | B4: Клас/ розділ/ група/ рахунок | I4: Актив/ пасив | J4: Обороти за місяць | Q4: Сальдо
J5: дебет | M5: кредит | Q5: усього | R5: НВ | S5: ІВ
B6: номер | F6: назва | J6: усього | K6: НВ | L6: ІВ | M6: усього | O6: НВ | P6: ІВ
A7: 1 | B7: 2 | F7: 3 | I7: 4 | J7: 5 | K7: 6 | L7: 7 | M7: 8 | O7: 9 | P7: 10 | Q7: 11 | R7: 12 | S7: 13
A8: 1 | B8: Балансові рахунки
A9: 2 | B9: Активи
A10: 3 | B10: Класи 1 - 4
A11: 4 | B11: Клас 1 | C11: 10 | D11: 100 | F11: 1001 | H11: Банкноти та монети в касі банку | I11: А | J11: 0 | K11: 0 | L11: 0 | M11: 0 | O11: 0 | P11: 0 | Q11: 0 | R11: 0 | S11: 0
A12: 5 | F12: 1002 | H12: Банкноти та монети в касі відділень банку | I12: А | J12: 5914005.9 | K12: 3084127.6 | L12: 2829878.3 | M12: 5943978.8 | O12: 3071289.4 | P12: 2872689.4 | Q12: 251905.6 | R12: 114771.12 | S12: 137134.49
A13: 6 | F13: 1004 | H13: Банкноти та монети в банкоматах | I13: А | J13: 4182370.7 | K13: 2136668.1 | L13: 2045702.6 | M13: 4168093.5 | O13: 2127828.4 | P13: 2040265.2 | Q13: 143784.34 | R13: 108761.99 | S13: 35022.355
A14: 7 | F14: 1005 | H14: Банкноти та монети, інкасовані до перерахування | I14: А | J14: 9057.9186 | K14: 9057.9186 | L14: 0 | M14: 9057.9186 | O14: 9057.9186 | P14: 0 | Q14: 0 | R14: 0 | S14: 0
A15: 8 | F15: 1006 | H15: Банкноти та монети на зберіганні в інкасаторській компанії | I15: А | J15: 0 | K15: 0 | L15: 0 | M15: 0 | O15: 0 | P15: 0 | Q15: 0 | R15: 0 | S15: 0
A16: 9 | F16: 1007 | H16: Банкноти та монети в дорозі | I16: А | J16: 6356298.7 | K16: 3256552.9 | L16: 3099745.8 | M16: 6356298.7 | O16: 3256552.9 | P16: 3099745.8 | Q16: 0 | R16: 0 | S16: 0
A17: 10 | F17: Група 100 - Усього | J17: 16461733 | K17: 8486406.6 | L17: 7975326.7 | M17: 16477429 | O17: 8464728.6 | P17: 8012700.3 | Q17: 395689.95 | R17: 223533.11 | S17: 172156.84
A18: 11 | D18: 101 | F18: 1011 | H18: Дорожні чеки в касі банку | I18: А | J18: 0 | K18: 0 | L18: 0 | M18: 0 | O18: 0 | P18: 0 | Q18: 0 | R18: 0 | S18: 0
A19: 12 | F19: 1012 | H19: Дорожні чеки в касі відділень банку | I19: А | J19: 0 | K19: 0 | L19: 0 | M19: 0 | O19: 0 | P19: 0 | Q19: 0 | R19: 0 | S19: 0
A20: 13 | F20: Група 101 - Усього | J20: 0 | K20: 0 | L20: 0 | M20: 0 | O20: 0 | P20: 0 | Q20: 0 | R20: 0 | S20: 0
A21: 14 | D21: 109 | F21: 1090 | H21: Резерви за готівковими коштами, наявність яких є непідтвердженою | I21: П | J21: 0 | K21: 0 | L21: 0 | M21: 0 | O21: 0 | P21: 0 | Q21: 0 | R21: 0 | S21: 0
A22: 15 | F22: Група 109 - Усього | J22: 0 | K22: 0 | L22: 0 | M22: 0 | O22: 0 | P22: 0 | Q22: 0 | R22: 0 | S22: 0
A23: 16 | D23: Розділ 10 - Усього | J23: 16461733 | K23: 8486406.6 | L23: 7975326.7 | M23: 16477429 | O23: 8464728.6 | P23: 8012700.3 | Q23: 395689.95 | R23: 223533.11 | S23: 172156.84
A24: 17 | C24: 11 | D24: 110 | F24: 1101 | H24: Банківські метали в банку | I24: А | J24: 0 | K24: 0 | L24: 0 | M24: 0 | O24: 0 | P24: 0 | Q24: 0 | R24: 0 | S24: 0
A25: 18 | F25: 1102 | H25: Банківські метали у відділенні банку | I25: А | J25: 407.81537 | K25: 0 | L25: 407.81537 | M25: 1703.0032 | O25: 0 | P25: 1703.0032 | Q25: 2518.5548 | R25: 0 | S25: 2518.5548
A26: 19 | F26: 1107 | H26: Банківські метали в дорозі | I26: А | J26: 0 | K26: 0 | L26: 0 | M26: 0 | O26: 0 | P26: 0 | Q26: 0 | R26: 0 | S26: 0
A27: 20 | F27: Група 110 - Усього | J27: 407.81537 | K27: 0 | L27: 407.81537 | M27: 1703.0032 | O27: 0 | P27: 1703.0032 | Q27: 2518.5548 | R27: 0 | S27: 2518.5548
A28: 21 | D28: 119 | F28: 1190 | H28: Резерви за банківськими металами, наявність яких є непідтвердженою | I28: П | J28: 0 | K28: 0 | L28: 0 | M28: 0 | O28: 0 | P28: 0 | Q28: 0 | R28: 0 | S28: 0
A29: 22 | F29: Група 119 - Усього | J29: 0 | K29: 0 | L29: 0 | M29: 0 | O29: 0 | P29: 0 | Q29: 0 | R29: 0 | S29: 0
A30: 23 | D30: Розділ 11 - Усього | J30: 407.81537 | K30: 0 | L30: 407.81537 | M30: 1703.0032 | O30: 0 | P30: 1703.0032 | Q30: 2518.5548 | R30: 0 | S30: 2518.5548
A31: 24 | C31: 12 | D31: 120 | F31: 1200 | H31: Кореспондентський рахунок банку в Національному банку України | I31: А | J31: 31603437 | K31: 31603437 | L31: 0 | M31: 31126964 | O31: 31126964 | P31: 0 | Q31: 920992.33 | R31: 920992.33 | S31: 0
A32: 25 | F32: 1202 | H32: Кошти банків за рахунками умовного зберігання (ескроу) у Національному банку України | I32: А | J32: 0 | K32: 0 | L32: 0 | M32: 0 | O32: 0 | P32: 0 | Q32: 0 | R32: 0 | S32: 0
A33: 26 | F33: 1205 | H33: Кошти банків для забезпечення виконання зобов’язань перед Національним банком України за кредитами, наданими банкам, та операціями своп процентної ставки | I33: А | J33: 0 | K33: 0 | L33: 0 | M33: 0 | O33: 0 | P33: 0 | Q33: 0 | R33: 0 | S33: 0
A34: 27 | F34: 1208 | H34: Нараховані доходи за коштами на вимогу в Національному банку України | I34: А | J34: 0 | K34: 0 | L34: 0 | M34: 0 | O34: 0 | P34: 0 | Q34: 0 | R34: 0 | S34: 0
A35: 28 | F35: Група 120 - Усього | J35: 31603437 | K35: 31603437 | L35: 0 | M35: 31126964 | O35: 31126964 | P35: 0 | Q35: 920992.33 | R35: 920992.33 | S35: 0
A36: 29 | D36: Розділ 12 - Усього | J36: 31603437 | K36: 31603437 | L36: 0 | M36: 31126964 | O36: 31126964 | P36: 0 | Q36: 920992.33 | R36: 920992.33 | S36: 0
A37: 30 | C37: 14 | D37: 140 | F37: 1400 | H37: Облігації внутрішньої державної позики, що рефінансуються Національним банком України, які обліковуються за справедливою вартістю через прибутки/збитки | I37: А | J37: 0 | K37: 0 | L37: 0 | M37: 0 | O37: 0 | P37: 0 | Q37: 0 | R37: 0 | S37: 0
A38: 31 | F38: 1405 | H38: Переоцінка боргових цінних паперів, що рефінансуються Національним банком України, які обліковуються за справедливою вартістю через прибутки/збитки | I38: А | J38: 0 | K38: 0 | L38: 0 | M38: 0 | O38: 0 | P38: 0 | Q38: 0 | R38: 0 | S38: 0
A39: 32 | I39: П | J39: 0 | K39: 0 | L39: 0 | M39: 0 | O39: 0 | P39: 0 | Q39: 0 | R39: 0 | S39: 0
A40: 33 | F40: 1406 | H40: Неамортизована премія/дисконт за борговими цінними паперами, що рефінансуються Національним банком України, які обліковуються за справедливою вартістю через прибутки/збитки | I40: А | J40: 0 | K40: 0 | L40: 0 | M40: 0 | O40: 0 | P40: 0 | Q40: 0 | R40: 0 | S40: 0
...

Sheet  36АТ "Райффайзен Банк" 
A1: Зміст
B2: Оборотно-сальдовий баланс банку АТ "Райффайзен Банк" за станом на 01.03.2026
B3: (тис грн)
A4: Номер з/п | B4: Клас/ розділ/ група/ рахунок | I4: Актив/ пасив | J4: Обороти за місяць | Q4: Сальдо
J5: дебет | M5: кредит | Q5: усього | R5: НВ | S5: ІВ
B6: номер | F6: назва | J6: усього | K6: НВ | L6: ІВ | M6: усього | O6: НВ | P6: ІВ
A7: 1 | B7: 2 | F7: 3 | I7: 4 | J7: 5 | K7: 6 | L7: 7 | M7: 8 | O7: 9 | P7: 10 | Q7: 11 | R7: 12 | S7: 13
A8: 1 | B8: Балансові рахунки
A9: 2 | B9: Активи
A10: 3 | B10: Класи 1 - 4
A11: 4 | B11: Клас 1 | C11: 10 | D11: 100 | F11: 1001 | H11: Банкноти та монети в касі банку | I11: А | J11: 27799241 | K11: 16977007 | L11: 10822234 | M11: 27866755 | O11: 16869992 | P11: 10996763 | Q11: 4153591.9 | R11: 1261063.6 | S11: 2892528.3
A12: 5 | F12: 1002 | H12: Банкноти та монети в касі відділень банку | I12: А | J12: 47793586 | K12: 22796032 | L12: 24997554 | M12: 47679391 | O12: 23370904 | P12: 24308487 | Q12: 5039857.2 | R12: 1754011.7 | S12: 3285845.5
A13: 6 | F13: 1004 | H13: Банкноти та монети в банкоматах | I13: А | J13: 17073488 | K13: 16958904 | L13: 114583.72 | M13: 17199240 | O13: 17086163 | P13: 113076.88 | Q13: 2617846.6 | R13: 2577793.1 | S13: 40053.48
A14: 7 | F14: 1005 | H14: Банкноти та монети, інкасовані до перерахування | I14: А | J14: 1227183.3 | K14: 1227183.3 | L14: 0 | M14: 1227183.3 | O14: 1227183.3 | P14: 0 | Q14: 0 | R14: 0 | S14: 0
A15: 8 | F15: 1006 | H15: Банкноти та монети на зберіганні в інкасаторській компанії | I15: А | J15: 0 | K15: 0 | L15: 0 | M15: 0 | O15: 0 | P15: 0 | Q15: 0 | R15: 0 | S15: 0
A16: 9 | F16: 1007 | H16: Банкноти та монети в дорозі | I16: А | J16: 65050454 | K16: 36481549 | L16: 28568906 | M16: 65069025 | O16: 36654667 | P16: 28414358 | Q16: 2547928.4 | R16: 470061.02 | S16: 2077867.4
A17: 10 | F17: Група 100 - Усього | J17: 1.5894395e+08 | K17: 94440675 | L17: 64503277 | M17: 1.590416e+08 | O17: 95208910 | P17: 63832685 | Q17: 14359224 | R17: 6062929.5 | S17: 8296294.6
A18: 11 | D18: 101 | F18: 1011 | H18: Дорожні чеки в касі банку | I18: А | J18: 0 | K18: 0 | L18: 0 | M18: 0 | O18: 0 | P18: 0 | Q18: 0 | R18: 0 | S18: 0
A19: 12 | F19: 1012 | H19: Дорожні чеки в касі відділень банку | I19: А | J19: 0 | K19: 0 | L19: 0 | M19: 0 | O19: 0 | P19: 0 | Q19: 0 | R19: 0 | S19: 0
A20: 13 | F20: Група 101 - Усього | J20: 0 | K20: 0 | L20: 0 | M20: 0 | O20: 0 | P20: 0 | Q20: 0 | R20: 0 | S20: 0
A21: 14 | D21: 109 | F21: 1090 | H21: Резерви за готівковими коштами, наявність яких є непідтвердженою | I21: П | J21: 9618.22 | K21: 9618.22 | L21: 0 | M21: 9618.22 | O21: 9618.22 | P21: 0 | Q21: -9618.22 | R21: -9618.22 | S21: 0
A22: 15 | F22: Група 109 - Усього | J22: 9618.22 | K22: 9618.22 | L22: 0 | M22: 9618.22 | O22: 9618.22 | P22: 0 | Q22: -9618.22 | R22: -9618.22 | S22: 0
A23: 16 | D23: Розділ 10 - Усього | J23: 1.5895357e+08 | K23: 94450293 | L23: 64503277 | M23: 1.5905121e+08 | O23: 95218528 | P23: 63832685 | Q23: 14349606 | R23: 6053311.3 | S23: 8296294.6
A24: 17 | C24: 11 | D24: 110 | F24: 1101 | H24: Банківські метали в банку | I24: А | J24: 0 | K24: 0 | L24: 0 | M24: 0 | O24: 0 | P24: 0 | Q24: 0 | R24: 0 | S24: 0
A25: 18 | F25: 1102 | H25: Банківські метали у відділенні банку | I25: А | J25: 0 | K25: 0 | L25: 0 | M25: 0 | O25: 0 | P25: 0 | Q25: 0 | R25: 0 | S25: 0
A26: 19 | F26: 1107 | H26: Банківські метали в дорозі | I26: А | J26: 0 | K26: 0 | L26: 0 | M26: 0 | O26: 0 | P26: 0 | Q26: 0 | R26: 0 | S26: 0
A27: 20 | F27: Група 110 - Усього | J27: 0 | K27: 0 | L27: 0 | M27: 0 | O27: 0 | P27: 0 | Q27: 0 | R27: 0 | S27: 0
A28: 21 | D28: 119 | F28: 1190 | H28: Резерви за банківськими металами, наявність яких є непідтвердженою | I28: П | J28: 0 | K28: 0 | L28: 0 | M28: 0 | O28: 0 | P28: 0 | Q28: 0 | R28: 0 | S28: 0
A29: 22 | F29: Група 119 - Усього | J29: 0 | K29: 0 | L29: 0 | M29: 0 | O29: 0 | P29: 0 | Q29: 0 | R29: 0 | S29: 0
A30: 23 | D30: Розділ 11 - Усього | J30: 0 | K30: 0 | L30: 0 | M30: 0 | O30: 0 | P30: 0 | Q30: 0 | R30: 0 | S30: 0
A31: 24 | C31: 12 | D31: 120 | F31: 1200 | H31: Кореспондентський рахунок банку в Національному банку України | I31: А | J31: 7.9929295e+08 | K31: 7.9929295e+08 | L31: 0 | M31: 8.0261565e+08 | O31: 8.0261565e+08 | P31: 0 | Q31: 16759705 | R31: 16759705 | S31: 0
A32: 25 | F32: 1202 | H32: Кошти банків за рахунками умовного зберігання (ескроу) у Національному банку України | I32: А | J32: 0 | K32: 0 | L32: 0 | M32: 0 | O32: 0 | P32: 0 | Q32: 0 | R32: 0 | S32: 0
A33: 26 | F33: 1205 | H33: Кошти банків для забезпечення виконання зобов’язань перед Національним банком України за кредитами, наданими банкам, та операціями своп процентної ставки | I33: А | J33: 0 | K33: 0 | L33: 0 | M33: 0 | O33: 0 | P33: 0 | Q33: 0 | R33: 0 | S33: 0
A34: 27 | F34: 1208 | H34: Нараховані доходи за коштами на вимогу в Національному банку України | I34: А | J34: 0 | K34: 0 | L34: 0 | M34: 0 | O34: 0 | P34: 0 | Q34: 0 | R34: 0 | S34: 0
A35: 28 | F35: Група 120 - Усього | J35: 7.9929295e+08 | K35: 7.9929295e+08 | L35: 0 | M35: 8.0261565e+08 | O35: 8.0261565e+08 | P35: 0 | Q35: 16759705 | R35: 16759705 | S35: 0
A36: 29 | D36: Розділ 12 - Усього | J36: 7.9929295e+08 | K36: 7.9929295e+08 | L36: 0 | M36: 8.0261565e+08 | O36: 8.0261565e+08 | P36: 0 | Q36: 16759705 | R36: 16759705 | S36: 0
A37: 30 | C37: 14 | D37: 140 | F37: 1400 | H37: Облігації внутрішньої державної позики, що рефінансуються Національним банком України, які обліковуються за справедливою вартістю через прибутки/збитки | I37: А | J37: 3851399.2 | K37: 3742391 | L37: 109008.22 | M37: 3935099.8 | O37: 3834430 | P37: 100669.79 | Q37: 5623716.1 | R37: 5554324 | S37: 69392.113
A38: 31 | F38: 1405 | H38: Переоцінка боргових цінних паперів, що рефінансуються Національним банком України, які обліковуються за справедливою вартістю через прибутки/збитки | I38: А | J38: 603378.37 | K38: 593690.91 | L38: 9687.4606 | M38: 527740.04 | O38: 517433.34 | P38: 10306.707 | Q38: 118388.58 | R38: 118137.17 | S38: 251.40946
A39: 32 | I39: П | J39: 0 | K39: 0 | L39: 0 | M39: 0 | O39: 0 | P39: 0 | Q39: -33161.668 | R39: -32982.402 | S39: -179.26523
A40: 33 | F40: 1406 | H40: Неамортизована премія/дисконт за борговими цінними паперами, що рефінансуються Національним банком України, які обліковуються за справедливою вартістю через прибутки/збитки | I40: А | J40: 147671.44 | K40: 146510.71 | L40: 1160.7273 | M40: 147473.05 | O40: 146731.15 | P40: 741.8955 | Q40: 96912.095 | R40: 96384.044 | S40: 528.05135
...

Sheet  43АТ "АЛЬТБАНК" 
A1: Зміст
B2: Оборотно-сальдовий баланс банку АТ "АЛЬТБАНК" за станом на 01.03.2026
B3: (тис грн)
A4: Номер з/п | B4: Клас/ розділ/ група/ рахунок | I4: Актив/ пасив | J4: Обороти за місяць | Q4: Сальдо
J5: дебет | M5: кредит | Q5: усього | R5: НВ | S5: ІВ
B6: номер | F6: назва | J6: усього | K6: НВ | L6: ІВ | M6: усього | O6: НВ | P6: ІВ
A7: 1 | B7: 2 | F7: 3 | I7: 4 | J7: 5 | K7: 6 | L7: 7 | M7: 8 | O7: 9 | P7: 10 | Q7: 11 | R7: 12 | S7: 13
A8: 1 | B8: Балансові рахунки
A9: 2 | B9: Активи
A10: 3 | B10: Класи 1 - 4
A11: 4 | B11: Клас 1 | C11: 10 | D11: 100 | F11: 1001 | H11: Банкноти та монети в касі банку | I11: А | J11: 15780.663 | K11: 10074.813 | L11: 5705.8503 | M11: 16786.722 | O11: 10262.014 | P11: 6524.7089 | Q11: 9787.4509 | R11: 1731.1779 | S11: 8056.273
A12: 5 | F12: 1002 | H12: Банкноти та монети в касі відділень банку | I12: А | J12: 42294.112 | K12: 28145.647 | L12: 14148.465 | M12: 38117.69 | O12: 26934.88 | P12: 11182.811 | Q12: 22716.854 | R12: 8197.072 | S12: 14519.782
A13: 6 | F13: 1004 | H13: Банкноти та монети в банкоматах | I13: А | J13: 14808.29 | K13: 14808.29 | L13: 0 | M13: 13817.26 | O13: 13817.26 | P13: 0 | Q13: 6979.94 | R13: 6979.94 | S13: 0
A14: 7 | F14: 1005 | H14: Банкноти та монети, інкасовані до перерахування | I14: А | J14: 0 | K14: 0 | L14: 0 | M14: 0 | O14: 0 | P14: 0 | Q14: 0 | R14: 0 | S14: 0
A15: 8 | F15: 1006 | H15: Банкноти та монети на зберіганні в інкасаторській компанії | I15: А | J15: 0 | K15: 0 | L15: 0 | M15: 0 | O15: 0 | P15: 0 | Q15: 0 | R15: 0 | S15: 0
A16: 9 | F16: 1007 | H16: Банкноти та монети в дорозі | I16: А | J16: 12267.49 | K16: 10755.56 | L16: 1511.9305 | M16: 12267.49 | O16: 10755.56 | P16: 1511.9305 | Q16: 0 | R16: 0 | S16: 0
A17: 10 | F17: Група 100 - Усього | J17: 85150.555 | K17: 63784.31 | L17: 21366.246 | M17: 80989.163 | O17: 61769.713 | P17: 19219.45 | Q17: 39484.245 | R17: 16908.19 | S17: 22576.055
A18: 11 | D18: 101 | F18: 1011 | H18: Дорожні чеки в касі банку | I18: А | J18: 0 | K18: 0 | L18: 0 | M18: 0 | O18: 0 | P18: 0 | Q18: 0 | R18: 0 | S18: 0
A19: 12 | F19: 1012 | H19: Дорожні чеки в касі відділень банку | I19: А | J19: 0 | K19: 0 | L19: 0 | M19: 0 | O19: 0 | P19: 0 | Q19: 0 | R19: 0 | S19: 0
A20: 13 | F20: Група 101 - Усього | J20: 0 | K20: 0 | L20: 0 | M20: 0 | O20: 0 | P20: 0 | Q20: 0 | R20: 0 | S20: 0
A21: 14 | D21: 109 | F21: 1090 | H21: Резерви за готівковими коштами, наявність яких є непідтвердженою | I21: П | J21: 0 | K21: 0 | L21: 0 | M21: 0 | O21: 0 | P21: 0 | Q21: 0 | R21: 0 | S21: 0
A22: 15 | F22: Група 109 - Усього | J22: 0 | K22: 0 | L22: 0 | M22: 0 | O22: 0 | P22: 0 | Q22: 0 | R22: 0 | S22: 0
A23: 16 | D23: Розділ 10 - Усього | J23: 85150.555 | K23: 63784.31 | L23: 21366.246 | M23: 80989.163 | O23: 61769.713 | P23: 19219.45 | Q23: 39484.245 | R23: 16908.19 | S23: 22576.055
A24: 17 | C24: 11 | D24: 110 | F24: 1101 | H24: Банківські метали в банку | I24: А | J24: 0 | K24: 0 | L24: 0 | M24: 0 | O24: 0 | P24: 0 | Q24: 0 | R24: 0 | S24: 0
A25: 18 | F25: 1102 | H25: Банківські метали у відділенні банку | I25: А | J25: 0 | K25: 0 | L25: 0 | M25: 0 | O25: 0 | P25: 0 | Q25: 0 | R25: 0 | S25: 0
A26: 19 | F26: 1107 | H26: Банківські метали в дорозі | I26: А | J26: 0 | K26: 0 | L26: 0 | M26: 0 | O26: 0 | P26: 0 | Q26: 0 | R26: 0 | S26: 0
A27: 20 | F27: Група 110 - Усього | J27: 0 | K27: 0 | L27: 0 | M27: 0 | O27: 0 | P27: 0 | Q27: 0 | R27: 0 | S27: 0
A28: 21 | D28: 119 | F28: 1190 | H28: Резерви за банківськими металами, наявність яких є непідтвердженою | I28: П | J28: 0 | K28: 0 | L28: 0 | M28: 0 | O28: 0 | P28: 0 | Q28: 0 | R28: 0 | S28: 0
A29: 22 | F29: Група 119 - Усього | J29: 0 | K29: 0 | L29: 0 | M29: 0 | O29: 0 | P29: 0 | Q29: 0 | R29: 0 | S29: 0
A30: 23 | D30: Розділ 11 - Усього | J30: 0 | K30: 0 | L30: 0 | M30: 0 | O30: 0 | P30: 0 | Q30: 0 | R30: 0 | S30: 0
A31: 24 | C31: 12 | D31: 120 | F31: 1200 | H31: Кореспондентський рахунок банку в Національному банку України | I31: А | J31: 6675209.8 | K31: 6675209.8 | L31: 0 | M31: 6788586 | O31: 6788586 | P31: 0 | Q31: 124950.28 | R31: 124950.28 | S31: 0
A32: 25 | F32: 1202 | H32: Кошти банків за рахунками умовного зберігання (ескроу) у Національному банку України | I32: А | J32: 0 | K32: 0 | L32: 0 | M32: 0 | O32: 0 | P32: 0 | Q32: 0 | R32: 0 | S32: 0
A33: 26 | F33: 1205 | H33: Кошти банків для забезпечення виконання зобов’язань перед Національним банком України за кредитами, наданими банкам, та операціями своп процентної ставки | I33: А | J33: 0 | K33: 0 | L33: 0 | M33: 0 | O33: 0 | P33: 0 | Q33: 0 | R33: 0 | S33: 0
A34: 27 | F34: 1208 | H34: Нараховані доходи за коштами на вимогу в Національному банку України | I34: А | J34: 0 | K34: 0 | L34: 0 | M34: 0 | O34: 0 | P34: 0 | Q34: 0 | R34: 0 | S34: 0
A35: 28 | F35: Група 120 - Усього | J35: 6675209.8 | K35: 6675209.8 | L35: 0 | M35: 6788586 | O35: 6788586 | P35: 0 | Q35: 124950.28 | R35: 124950.28 | S35: 0
A36: 29 | D36: Розділ 12 - Усього | J36: 6675209.8 | K36: 6675209.8 | L36: 0 | M36: 6788586 | O36: 6788586 | P36: 0 | Q36: 124950.28 | R36: 124950.28 | S36: 0
A37: 30 | C37: 14 | D37: 140 | F37: 1400 | H37: Облігації внутрішньої державної позики, що рефінансуються Національним банком України, які обліковуються за справедливою вартістю через прибутки/збитки | I37: А | J37: 0 | K37: 0 | L37: 0 | M37: 0 | O37: 0 | P37: 0 | Q37: 0 | R37: 0 | S37: 0
A38: 31 | F38: 1405 | H38: Переоцінка боргових цінних паперів, що рефінансуються Національним банком України, які обліковуються за справедливою вартістю через прибутки/збитки | I38: А | J38: 0 | K38: 0 | L38: 0 | M38: 0 | O38: 0 | P38: 0 | Q38: 0 | R38: 0 | S38: 0
A39: 32 | I39: П | J39: 0 | K39: 0 | L39: 0 | M39: 0 | O39: 0 | P39: 0 | Q39: 0 | R39: 0 | S39: 0
A40: 33 | F40: 1406 | H40: Неамортизована премія/дисконт за борговими цінними паперами, що рефінансуються Національним банком України, які обліковуються за справедливою вартістю через прибутки/збитки | I40: А | J40: 0 | K40: 0 | L40: 0 | M40: 0 | O40: 0 | P40: 0 | Q40: 0 | R40: 0 | S40: 0
...
