Workbook

Sheet Index
C2: Оборотно-сальдовий баланс банку* | D2: відповідно до Додатку 1 до постанови Правління Національного банку України
D3: від 15 березня 2018 року № 11 "Про встановлення переліку інформації, що підлягає обов'язковому опублікуванню банками України" (зі змінами)
D4: за даними статистичної звітності з файлів 02X "Дані про обороти та залишки на рахунках".
A5: NKB | B5: Порядковий номер | C5: Назва банку | D5: МФО | E5: ПРОЦЕНТИ ЗА ДЕПОЗИТНИМИ СЕРТИФІКАТАМИ (ДС), тис. грн | F5: ПРОЦЕНТИ ЗА ОВДП (ОВДП), тис.грн | G5: ПРОЦЕНТИ ЗА КРЕДИТАМИ ЗДУ | H5: ПРОЦЕНТИ ЗА КРЕДИТАМИ БІЗНЕСУ | I5: ПРОЦЕНТИ ЗА КРЕДИТАМИ НАСЕЛЕННЮ | J5: ПРОЦЕНТНІ ДОХОДИ ВСЬОГО (ПД), тис. грн | K5: ДС/ПД, % | L5: ДС до підсумку, % | M5: (ДС+ОВДП)/ПД, % | N5: ОВДП/ПД, % | O5: ОВДП до підсумку | P5: Обсяг ДС дебит (середні, поділено на кількість банк.днів) | Q5: Обсяг ДС кредит (середні, поділено на кількість банк.днів) | R5: Кошти в НБУ (кор.рахунок) (кредит) (код 1200) | S5: Кошти в НБУ (УСЬОГО) (кредит) (розділ 12) | T5: Проценти за поточними вкладами ДГ (код 7040) | U5: Проценти за строковими вкладами ДГ (код 7041) | V5: Кредити субʼєктам господарювання (р.20, р.23, 260) | W5: Кредити ЗДУ (р.21) | X5: Кредити фізичним особам (р. 22, 24, 262) | Y5: Кредити небанківським установам (265) | Z5: Прибуток звітного року (5040) | AA5: Збиток звітного року (5041) | AB5: Податок на прибуток (7900) | AC5: Інші податки (741) | AD5: Відрахування в резерви (770) | AE5: Загальні доходи (6) | AF5: Загальні витрати (7)
A6: 2 | B6: 1 | C6: АТ "Укрексімбанк" | D6: 322313 | E6: =' 2АТ "Укрексімбанк" '!$P$1139 | F6: =' 2АТ "Укрексімбанк" '!$P$1138 | G6: =' 2АТ "Укрексімбанк" '!$P$1150 | H6: =' 2АТ "Укрексімбанк" '!$P$1148 | I6: =' 2АТ "Укрексімбанк" '!$P$1149 | J6: =' 2АТ "Укрексімбанк" '!$P$1144 | K6: =IFERROR(E6/J6*100,0) | L6: =IFERROR(E6/SUM(E6:E6)*100,0) | M6: =IFERROR((E6+F6)/J6*100,0) | N6: =IFERROR(F6/J6*100,0) | O6: =IFERROR(F6/SUM(F6:F6)*100,0) | P6: =' 2АТ "Укрексімбанк" '!$J$1140 | Q6: =' 2АТ "Укрексімбанк" '!$N$1141 | R6: =' 2АТ "Укрексімбанк" '!$M$1142 | S6: =' 2АТ "Укрексімбанк" '!$M$1143 | T6: =' 2АТ "Укрексімбанк" '!$P$1151 | U6: =' 2АТ "Укрексімбанк" '!$P$1152 | V6: =' 2АТ "Укрексімбанк" '!$P$1154 | W6: =' 2АТ "Укрексімбанк" '!$P$1155 | X6: =' 2АТ "Укрексімбанк" '!$P$1156 | Y6: =' 2АТ "Укрексімбанк" '!$P$1157 | Z6: =' 2АТ "Укрексімбанк" '!$P$1158 | AA6: =' 2АТ "Укрексімбанк" '!$P$1159 | AB6: =' 2АТ "Укрексімбанк" '!$P$1160 | AC6: =' 2АТ "Укрексімбанк" '!$P$1161 | AD6: =' 2АТ "Укрексімбанк" '!$P$1162 | AE6: =' 2АТ "Укрексімбанк" '!$P$1163 | AF6: =' 2АТ "Укрексімбанк" '!$P$1164
A7: Всього | E7: =IFERROR(SUM(E6:E6),0) | F7: =IFERROR(SUM(F6:F6),0) | G7: =IFERROR(SUM(G6:G6),0) | H7: =IFERROR(SUM(H6:H6),0) | I7: =IFERROR(SUM(I6:I6),0) | J7: =IFERROR(SUM(J6:J6),0) | K7: =IFERROR(E7/J7*100,0) | L7: =IFERROR(E7/SUM(E6:E6)*100,0) | M7: =IFERROR((E7+F7)/J7*100,0) | N7: =IFERROR(F7/J7*100,0) | O7: =IFERROR(F7/SUM(F6:F6)*100,0) | P7: =IFERROR(SUM(P6:P6),0) | Q7: =IFERROR(SUM(Q6:Q6),0) | R7: =IFERROR(SUM(R6:R6),0) | S7: =IFERROR(SUM(S6:S6),0) | T7: =IFERROR(SUM(T6:T6),0) | U7: =IFERROR(SUM(U6:U6),0) | V7: =IFERROR(SUM(V6:V6),0) | W7: =IFERROR(SUM(W6:W6),0) | ... AF7: =IFERROR(SUM(AF6:AF6),0)
A8: Державні банки | E8: =IFERROR(SUM(E6),0) | F8: =IFERROR(SUM(F6),0) | G8: =IFERROR(SUM(G6),0) | H8: =IFERROR(SUM(H6),0) | I8: =IFERROR(SUM(I6),0) | J8: =IFERROR(SUM(J6),0) | K8: =IFERROR(E8/J8*100,0) | L8: =IFERROR(E8/E7*100,0) | M8: =IFERROR(SUM(M6),0) | N8: =IFERROR(SUM(N6),0) | O8: =IFERROR(F8/F7*100,0) | P8: =IFERROR(SUM(P6),0) | Q8: =IFERROR(SUM(Q6),0) | R8: =IFERROR(SUM(R6),0) | S8: =IFERROR(SUM(S6),0) | T8: =IFERROR(SUM(T6),0) | U8: =IFERROR(SUM(U6),0) | V8: =IFERROR(SUM(V6),0) | W8: =IFERROR(SUM(W6),0) | ... AF8: =IFERROR(SUM(AF6),0)
A9: Банки з іноземним капіталом | E9: =0 | F9: =0 | G9: =0 | H9: =0 | I9: =0 | J9: =0 | K9: =IFERROR(E9/J9*100,0) | L9: =IFERROR(E9/E7*100,0) | M9: =0 | N9: =0 | O9: =IFERROR(F9/F7*100,0) | P9: =0 | Q9: =0 | R9: =0 | S9: =0 | T9: =0 | U9: =0 | V9: =0 | W9: =0 | ... AF9: =0
A10: Банки з українським приватним капіталом | E10: =IFERROR(E7-E8-E9,0) | F10: =IFERROR(F7-F8-F9,0) | G10: =IFERROR(G7-G8-G9,0) | H10: =IFERROR(H7-H8-H9,0) | I10: =IFERROR(I7-I8-I9,0) | J10: =IFERROR(J7-J8-J9,0) | K10: =IFERROR(E10/J10*100,0) | L10: =IFERROR(E10/E7*100,0) | M10: =IFERROR(M7-M8-M9,0) | N10: =IFERROR(N7-N8-N9,0) | O10: =IFERROR(F10/F7*100,0) | P10: =IFERROR(P7-P8-P9,0) | Q10: =IFERROR(Q7-Q8-Q9,0) | R10: =IFERROR(R7-R8-R9,0) | S10: =IFERROR(S7-S8-S9,0) | T10: =IFERROR(T7-T8-T9,0) | U10: =IFERROR(U7-U8-U9,0) | V10: =IFERROR(V7-V8-V9,0) | W10: =IFERROR(W7-W8-W9,0) | ... AF10: =IFERROR(AF7-AF8-AF9,0)
B12: Категорія | C12: ДС/ПД, % | H12: Категорія | I12: ДС до підсумку, %
B13: =A8 | C13: =IFERROR(K8,0) | H13: =A8 | I13: =IFERROR(L8,0)
B14: =A9 | C14: =IFERROR(K9,0) | H14: =A9 | I14: =IFERROR(L9,0)
B15: =A10 | C15: =IFERROR(K10,0) | H15: =A10 | I15: =IFERROR(L10,0)

Sheet Indicator_Summary
A1: ПРОЦЕНТНІ ДОХОДИ банків
B2: млрд | C2: %
A3: Депозитні сертифікати | B3: =SUM(Index!E6:E6)/1000000 | C3: =B3/B8 * 100
A4: ОВДП | B4: =SUM(Index!F6:F6)/1000000 | C4: =B4/B8 * 100
A5: Кредити бізнесу | B5: =SUM(Index!H6:H6)/1000000 | C5: =B5/B8 * 100
A6: Кредити населенню | B6: =SUM(Index!I6:I6)/1000000 | C6: =B6/B8 * 100
A7: Інші процентні доходи | B7: =B8 - (B3 +B4 +B5 +B6) | C7: =B7/B8 * 100
A8: ВСЬОГО | B8: =SUM(Index!J6:J6)/1000000 | C8: 100

Sheet Pivot_Data
A1: bank_code | B1: bank_name | C1: bank_class | D1: id | E1: indicator | F1: name | G1: category | H1: debit_total | I1: debit_nc | J1: debit_ic | K1: credit_total | L1: credit_nc | M1: credit_ic | N1: balance_total | O1: balance_nc | P1: balance_ic
A2: 2 | B2: АТ "Укрексімбанк" | C2: Державний | D2: 1001 | E2: (без привʼязки) | F2: Банкноти та монети в касі банку | G2: А | H2: 2881154.5 | I2: 1258377.3 | J2: 1622777.2 | K2: 2741564.6 | L2: 1220518.4 | M2: 1521046.2 | N2: 827366.58 | O2: 181416.63 | P2: 645949.94
A3: 2 | B3: АТ "Укрексімбанк" | C3: Державний | D3: 1002 | E3: (без привʼязки) | F3: Банкноти та монети в касі відділень банку | G3: А | H3: 421596.77 | I3: 177262.1 | J3: 244334.67 | K3: 420605.54 | L3: 178404.18 | M3: 242201.35 | N3: 68413.231 | O3: 15938.651 | P3: 52474.58
A4: 2 | B4: АТ "Укрексімбанк" | C4: Державний | D4: 1004 | E4: (без привʼязки) | F4: Банкноти та монети в банкоматах | G4: А | H4: 1424777.4 | I4: 1424777.4 | J4: 0 | K4: 1427186.2 | L4: 1427186.2 | M4: 0 | N4: 345970.89 | O4: 345970.89 | P4: 0
A5: 2 | B5: АТ "Укрексімбанк" | C5: Державний | D5: 1005 | E5: (без привʼязки) | F5: Банкноти та монети, інкасовані до перерахування | G5: А | H5: 94970.078 | I5: 94970.078 | J5: 0 | K5: 94970.078 | L5: 94970.078 | M5: 0 | N5: 0 | O5: 0 | P5: 0
A6: 2 | B6: АТ "Укрексімбанк" | C6: Державний | D6: 1006 | E6: (без привʼязки) | F6: Банкноти та монети на зберіганні в інкасаторській компанії | G6: А | H6: 0 | I6: 0 | J6: 0 | K6: 0 | L6: 0 | M6: 0 | N6: 0 | O6: 0 | P6: 0
A7: 2 | B7: АТ "Укрексімбанк" | C7: Державний | D7: 1007 | E7: (без привʼязки) | F7: Банкноти та монети в дорозі | G7: А | H7: 880991.48 | I7: 256979.65 | J7: 624011.83 | K7: 911560.8 | L7: 261956.45 | M7: 649604.35 | N7: 0 | O7: 0 | P7: 0
A8: 2 | B8: АТ "Укрексімбанк" | C8: Державний | D8: 1011 | E8: (без привʼязки) | F8: Дорожні чеки в касі банку | G8: А | H8: 0 | I8: 0 | J8: 0 | K8: 0 | L8: 0 | M8: 0 | N8: 0 | O8: 0 | P8: 0
A9: 2 | B9: АТ "Укрексімбанк" | C9: Державний | D9: 1012 | E9: (без привʼязки) | F9: Дорожні чеки в касі відділень банку | G9: А | H9: 0 | I9: 0 | J9: 0 | K9: 0 | L9: 0 | M9: 0 | N9: 0 | O9: 0 | P9: 0
A10: 2 | B10: АТ "Укрексімбанк" | C10: Державний | D10: 1090 | E10: (без привʼязки) | F10: Резерви за готівковими коштами, наявність яких є непідтвердженою | G10: П | H10: 533.62252 | I10: 0 | J10: 533.62252 | K10: 785.03309 | L10: 0 | M10: 785.03309 | N10: -50810.589 | O10: -5377.8999 | P10: -45432.689
A11: 2 | B11: АТ "Укрексімбанк" | C11: Державний | D11: 1101 | E11: (без привʼязки) | F11: Банківські метали в банку | G11: А | H11: 0 | I11: 0 | J11: 0 | K11: 0 | L11: 0 | M11: 0 | N11: 0 | O11: 0 | P11: 0
A12: 2 | B12: АТ "Укрексімбанк" | C12: Державний | D12: 1102 | E12: (без привʼязки) | F12: Банківські метали у відділенні банку | G12: А | H12: 0 | I12: 0 | J12: 0 | K12: 0 | L12: 0 | M12: 0 | N12: 0 | O12: 0 | P12: 0
A13: 2 | B13: АТ "Укрексімбанк" | C13: Державний | D13: 1107 | E13: (без привʼязки) | F13: Банківські метали в дорозі | G13: А | H13: 0 | I13: 0 | J13: 0 | K13: 0 | L13: 0 | M13: 0 | N13: 0 | O13: 0 | P13: 0
... A1303: 2 | B1303: АТ "Укрексімбанк" | C1303: Державний | D1303: 9916 | E1303: (без привʼязки) | F1303: 0 | G1303: П | H1303: 0 | I1303: 0 | J1303: 0 | K1303: 0 | L1303: 0 | M1303: 0 | N1303: 0 | O1303: 0 | P1303: 0

Sheet Зміст
B2: Оборотно-сальдовий баланс банку | C2: відповідно до підпункту 1 пункту 2 постанови Правління Національного банку України
C3: від 15 березня 2018 року № 11 “Про встановлення переліку інформації, що підлягає обов'язковому опублікуванню банками України” (зі змінами)
C4: за даними статистичної звітності з файлу 02X “Дані про обороти та залишки на рахунках”.
A6: NKB | B6: Назва | C6: МФО
A7: 2 | B7: АТ "Укрексімбанк" | C7: 322313
A8: 6 | B8: АТ "ОЩАДБАНК" | C8: 300465
A9: 29 | B9: АТ "БАНК АЛЬЯНС" | C9: 300119
A10: 36 | B10: АТ "Райффайзен Банк" | C10: 300335
A11: 43 | B11: АТ "АЛЬТБАНК" | C11: 320940
A12: 46 | B12: АТ КБ "ПриватБанк" | C12: 305299
A13: 49 | B13: Полікомбанк | C13: 353100
A14: 62 | B14: АТ "ТАСКОМБАНК" | C14: 339500
A15: 72 | B15: ПрАТ "БАНК ФАМІЛЬНИЙ" | C15: 334840
A16: 88 | B16: АТ "КРЕДОБАНК" | C16: 325365
A17: 91 | B17: АТ АКБ "Львів" | C17: 325268
... A66: 774 | B66: АТ "РВС БАНК"* | C66: 339072
A68: * Неплатоспроможний банк.

Sheet   2АТ "Укрексімбанк" 
A1: Зміст
B2: Оборотно-сальдовий баланс банку АТ "Укрексімбанк" за станом на 01.12.2025
B3: (тис грн)
A4: Номер з/п | B4: Клас/ розділ/ група/ рахунок | I4: Актив/ пасив | J4: Обороти за місяць | Q4: Сальдо
J5: дебет | M5: кредит | Q5: усього | R5: НВ | S5: ІВ
B6: номер | F6: назва | J6: усього | K6: НВ | L6: ІВ | M6: усього | O6: НВ | P6: ІВ
A7: 1 | B7: 2 | F7: 3 | I7: 4 | J7: 5 | K7: 6 | L7: 7 | M7: 8 | O7: 9 | P7: 10 | Q7: 11 | R7: 12 | S7: 13
A8: 1 | B8: Балансові рахунки
A9: 2 | B9: Активи
A10: 3 | B10: Класи 1 - 4
A11: 4 | B11: Клас 1 | C11: 10 | D11: 100 | F11: 1001 | H11: Банкноти та монети в касі банку | I11: А | J11: 2881154.5 | K11: 1258377.3 | L11: 1622777.2 | M11: 2741564.6 | O11: 1220518.4 | P11: 1521046.2 | Q11: 827366.58 | R11: 181416.63 | S11: 645949.94
A12: 5 | F12: 1002 | H12: Банкноти та монети в касі відділень банку | I12: А | J12: 421596.77 | K12: 177262.1 | L12: 244334.67 | M12: 420605.54 | O12: 178404.18 | P12: 242201.35 | Q12: 68413.231 | R12: 15938.651 | S12: 52474.58
A13: 6 | F13: 1004 | H13: Банкноти та монети в банкоматах | I13: А | J13: 1424777.4 | K13: 1424777.4 | L13: 0 | M13: 1427186.2 | O13: 1427186.2 | P13: 0 | Q13: 345970.89 | R13: 345970.89 | S13: 0
A14: 7 | F14: 1005 | H14: Банкноти та монети, інкасовані до перерахування | I14: А | J14: 94970.078 | K14: 94970.078 | L14: 0 | M14: 94970.078 | O14: 94970.078 | P14: 0 | Q14: 0 | R14: 0 | S14: 0
A15: 8 | F15: 1006 | H15: Банкноти та монети на зберіганні в інкасаторській компанії | I15: А | J15: 0 | K15: 0 | L15: 0 | M15: 0 | O15: 0 | P15: 0 | Q15: 0 | R15: 0 | S15: 0
A16: 9 | F16: 1007 | H16: Банкноти та монети в дорозі | I16: А | J16: 880991.48 | K16: 256979.65 | L16: 624011.83 | M16: 911560.8 | O16: 261956.45 | P16: 649604.35 | Q16: 0 | R16: 0 | S16: 0
A17: 10 | F17: Група 100 - Усього | J17: 5703490.3 | K17: 3212366.5 | L17: 2491123.7 | M17: 5595887.3 | O17: 3183035.4 | P17: 2412851.9 | Q17: 1241750.7 | R17: 543326.17 | S17: 698424.52
A18: 11 | D18: 101 | F18: 1011 | H18: Дорожні чеки в касі банку | I18: А | J18: 0 | K18: 0 | L18: 0 | M18: 0 | O18: 0 | P18: 0 | Q18: 0 | R18: 0 | S18: 0
A19: 12 | F19: 1012 | H19: Дорожні чеки в касі відділень банку | I19: А | J19: 0 | K19: 0 | L19: 0 | M19: 0 | O19: 0 | P19: 0 | Q19: 0 | R19: 0 | S19: 0
A20: 13 | F20: Група 101 - Усього | J20: 0 | K20: 0 | L20: 0 | M20: 0 | O20: 0 | P20: 0 | Q20: 0 | R20: 0 | S20: 0
A21: 14 | D21: 109 | F21: 1090 | H21: Резерви за готівковими коштами, наявність яких є непідтвердженою | I21: П | J21: 533.62252 | K21: 0 | L21: 533.62252 | M21: 785.03309 | O21: 0 | P21: 785.03309 | Q21: -50810.589 | R21: -5377.8999 | S21: -45432.689
A22: 15 | F22: Група 109 - Усього | J22: 533.62252 | K22: 0 | L22: 533.62252 | M22: 785.03309 | O22: 0 | P22: 785.03309 | Q22: -50810.589 | R22: -5377.8999 | S22: -45432.689
A23: 16 | D23: Розділ 10 - Усього | J23: 5704023.9 | K23: 3212366.5 | L23: 2491657.3 | M23: 5596672.3 | O23: 3183035.4 | P23: 2413636.9 | Q23: 1190940.1 | R23: 537948.27 | S23: 652991.84
A24: 17 | C24: 11 | D24: 110 | F24: 1101 | H24: Банківські метали в банку | I24: А | J24: 0 | K24: 0 | L24: 0 | M24: 0 | O24: 0 | P24: 0 | Q24: 0 | R24: 0 | S24: 0
A25: 18 | F25: 1102 | H25: Банківські метали у відділенні банку | I25: А | J25: 0 | K25: 0 | L25: 0 | M25: 0 | O25: 0 | P25: 0 | Q25: 0 | R25: 0 | S25: 0
A26: 19 | F26: 1107 | H26: Банківські метали в дорозі | I26: А | J26: 0 | K26: 0 | L26: 0 | M26: 0 | O26: 0 | P26: 0 | Q26: 0 | R26: 0 | S26: 0
A27: 20 | F27: Група 110 - Усього | J27: 0 | K27: 0 | L27: 0 | M27: 0 | O27: 0 | P27: 0 | Q27: 0 | R27: 0 | S27: 0
A28: 21 | D28: 119 | F28: 1190 | H28: Резерви за банківськими металами, наявність яких є непідтвердженою | I28: П | J28: 0 | K28: 0 | L28: 0 | M28: 0 | O28: 0 | P28: 0 | Q28: 0 | R28: 0 | S28: 0
A29: 22 | F29: Група 119 - Усього | J29: 0 | K29: 0 | L29: 0 | M29: 0 | O29: 0 | P29: 0 | Q29: 0 | R29: 0 | S29: 0
A30: 23 | D30: Розділ 11 - Усього | J30: 0 | K30: 0 | L30: 0 | M30: 0 | O30: 0 | P30: 0 | Q30: 0 | R30: 0 | S30: 0
A31: 24 | C31: 12 | D31: 120 | F31: 1200 | H31: Кореспондентський рахунок банку в Національному банку України | I31: А | J31: 5.6606691e+08 | K31: 5.6606691e+08 | L31: 0 | M31: 5.616171e+08 | O31: 5.616171e+08 | P31: 0 | Q31: 22042210 | R31: 22042210 | S31: 0
A32: 25 | F32: 1202 | H32: Кошти банків за рахунками умовного зберігання (ескроу) у Національному банку України | I32: А | J32: 0 | K32: 0 | L32: 0 | M32: 0 | O32: 0 | P32: 0 | Q32: 0 | R32: 0 | S32: 0
A33: 26 | F33: 1205 | H33: Кошти банків для забезпечення виконання зобов’язань перед Національним банком України за кредитами, наданими банкам, та операціями своп процентної ставки | I33: А | J33: 0 | K33: 0 | L33: 0 | M33: 0 | O33: 0 | P33: 0 | Q33: 0 | R33: 0 | S33: 0
A34: 27 | F34: 1208 | H34: Нараховані доходи за коштами на вимогу в Національному банку України | I34: А | J34: 0 | K34: 0 | L34: 0 | M34: 0 | O34: 0 | P34: 0 | Q34: 0 | R34: 0 | S34: 0
A35: 28 | F35: Група 120 - Усього | J35: 5.6606691e+08 | K35: 5.6606691e+08 | L35: 0 | M35: 5.616171e+08 | O35: 5.616171e+08 | P35: 0 | Q35: 22042210 | R35: 22042210 | S35: 0
A36: 29 | D36: Розділ 12 - Усього | J36: 5.6606691e+08 | K36: 5.6606691e+08 | L36: 0 | M36: 5.616171e+08 | O36: 5.616171e+08 | P36: 0 | Q36: 22042210 | R36: 22042210 | S36: 0
A37: 30 | C37: 14 | D37: 140 | F37: 1400 | H37: Облігації внутрішньої державної позики, що рефінансуються Національним банком України, які обліковуються за справедливою вартістю через прибутки/збитки | I37: А | J37: 9461457.4 | K37: 5951813 | L37: 3509644.4 | M37: 12068323 | O37: 8995306 | P37: 3073017.2 | Q37: 13863168 | R37: 13246549 | S37: 616618.88
A38: 31 | F38: 1405 | H38: Переоцінка боргових цінних паперів, що рефінансуються Національним банком України, які обліковуються за справедливою вартістю через прибутки/збитки | I38: А | J38: 374584.69 | K38: 372410.19 | L38: 2174.4995 | M38: 2627750.8 | O38: 2625165.2 | P38: 2585.535 | Q38: 6054103.6 | R38: 6053531 | S38: 572.58176
A39: 32 | I39: П | J39: 0 | K39: 0 | L39: 0 | M39: 0 | O39: 0 | P39: 0 | Q39: -57653.272 | R39: -57281.832 | S39: -371.44051
A40: 33 | F40: 1406 | H40: Неамортизована премія/дисконт за борговими цінними паперами, що рефінансуються Національним банком України, які обліковуються за справедливою вартістю через прибутки/збитки | I40: А | J40: 76966.686 | K40: 72049.045 | L40: 4917.6409 | M40: 60453.482 | O40: 56658.297 | P40: 3795.1846 | Q40: 704401.07 | R40: 703238.51 | S40: 1162.5606
...
