Workbook

Sheet Index
C2: Оборотно-сальдовий баланс банку* | D2: відповідно до Додатку 1 до постанови Правління Національного банку України
D3: від 15 березня 2018 року № 11 "Про встановлення переліку інформації, що підлягає обов'язковому опублікуванню банками України" (зі змінами)
D4: за даними статистичної звітності з файлів 02X "Дані про обороти та залишки на рахунках".
A5: NKB | B5: Порядковий номер | C5: Назва банку | D5: МФО | E5: ПРОЦЕНТИ ЗА ДЕПОЗИТНИМИ СЕРТИФІКАТАМИ (ДС), тис. грн | F5: ПРОЦЕНТИ ЗА ОВДП (ОВДП), тис.грн | G5: ПРОЦЕНТИ ЗА КРЕДИТАМИ ЗДУ | H5: ПРОЦЕНТИ ЗА КРЕДИТАМИ БІЗНЕСУ | I5: ПРОЦЕНТИ ЗА КРЕДИТАМИ НАСЕЛЕННЮ | J5: ПРОЦЕНТНІ ДОХОДИ ВСЬОГО (ПД), тис. грн | K5: ДС/ПД, % | L5: ДС до підсумку, % | M5: (ДС+ОВДП)/ПД, % | N5: ОВДП/ПД, % | O5: ОВДП до підсумку | P5: Обсяг ДС дебит (середні, поділено на кількість банк.днів) | Q5: Обсяг ДС кредит (середні, поділено на кількість банк.днів) | R5: Кошти в НБУ (кор.рахунок) (кредит) (код 1200) | S5: Кошти в НБУ (УСЬОГО) (кредит) (розділ 12) | T5: Проценти за поточними вкладами ДГ (код 7040) | U5: Проценти за строковими вкладами ДГ (код 7041) | V5: Кредити субʼєктам господарювання (р.20, р.23, 260) | W5: Кредити ЗДУ (р.21) | X5: Кредити фізичним особам (р. 22, 24, 262) | Y5: Кредити небанківським установам (265) | Z5: Прибуток звітного року (5040) | AA5: Збиток звітного року (5041) | AB5: Податок на прибуток (7900) | AC5: Інші податки (741) | AD5: Відрахування в резерви (770) | AE5: Загальні доходи (6) | AF5: Загальні витрати (7)
A6: 2 | B6: 1 | C6: АТ "Укрексімбанк" | D6: 322313 | E6: =' 2АТ "Укрексімбанк" '!$P$1139 | F6: =' 2АТ "Укрексімбанк" '!$P$1138 | G6: =' 2АТ "Укрексімбанк" '!$P$1150 | H6: =' 2АТ "Укрексімбанк" '!$P$1148 | I6: =' 2АТ "Укрексімбанк" '!$P$1149 | J6: =' 2АТ "Укрексімбанк" '!$P$1144 | K6: =IFERROR(E6/J6*100,0) | L6: =IFERROR(E6/SUM(E6:E10)*100,0) | M6: =IFERROR((E6+F6)/J6*100,0) | N6: =IFERROR(F6/J6*100,0) | O6: =IFERROR(F6/SUM(F6:F10)*100,0) | P6: =' 2АТ "Укрексімбанк" '!$J$1140 | Q6: =' 2АТ "Укрексімбанк" '!$N$1141 | R6: =' 2АТ "Укрексімбанк" '!$M$1142 | S6: =' 2АТ "Укрексімбанк" '!$M$1143 | T6: =' 2АТ "Укрексімбанк" '!$P$1151 | U6: =' 2АТ "Укрексімбанк" '!$P$1152 | V6: =' 2АТ "Укрексімбанк" '!$P$1154 | W6: =' 2АТ "Укрексімбанк" '!$P$1155 | X6: =' 2АТ "Укрексімбанк" '!$P$1156 | Y6: =' 2АТ "Укрексімбанк" '!$P$1157 | Z6: =' 2АТ "Укрексімбанк" '!$P$1158 | AA6: =' 2АТ "Укрексімбанк" '!$P$1159 | AB6: =' 2АТ "Укрексімбанк" '!$P$1160 | AC6: =' 2АТ "Укрексімбанк" '!$P$1161 | AD6: =' 2АТ "Укрексімбанк" '!$P$1162 | AE6: =' 2АТ "Укрексімбанк" '!$P$1163 | AF6: =' 2АТ "Укрексімбанк" '!$P$1164
A7: 6 | B7: 2 | C7: АТ "Ощадбанк" | D7: 300465 | E7: =' 6АТ "Ощадбанк" '!$P$1139 | F7: =' 6АТ "Ощадбанк" '!$P$1138 | G7: =' 6АТ "Ощадбанк" '!$P$1150 | H7: =' 6АТ "Ощадбанк" '!$P$1148 | I7: =' 6АТ "Ощадбанк" '!$P$1149 | J7: =' 6АТ "Ощадбанк" '!$P$1144 | K7: =IFERROR(E7/J7*100,0) | L7: =IFERROR(E7/SUM(E6:E10)*100,0) | M7: =IFERROR((E7+F7)/J7*100,0) | N7: =IFERROR(F7/J7*100,0) | O7: =IFERROR(F7/SUM(F6:F10)*100,0) | P7: =' 6АТ "Ощадбанк" '!$J$1140 | Q7: =' 6АТ "Ощадбанк" '!$N$1141 | R7: =' 6АТ "Ощадбанк" '!$M$1142 | S7: =' 6АТ "Ощадбанк" '!$M$1143 | T7: =' 6АТ "Ощадбанк" '!$P$1151 | U7: =' 6АТ "Ощадбанк" '!$P$1152 | V7: =' 6АТ "Ощадбанк" '!$P$1154 | W7: =' 6АТ "Ощадбанк" '!$P$1155 | X7: =' 6АТ "Ощадбанк" '!$P$1156 | Y7: =' 6АТ "Ощадбанк" '!$P$1157 | Z7: =' 6АТ "Ощадбанк" '!$P$1158 | AA7: =' 6АТ "Ощадбанк" '!$P$1159 | AB7: =' 6АТ "Ощадбанк" '!$P$1160 | AC7: =' 6АТ "Ощадбанк" '!$P$1161 | AD7: =' 6АТ "Ощадбанк" '!$P$1162 | AE7: =' 6АТ "Ощадбанк" '!$P$1163 | AF7: =' 6АТ "Ощадбанк" '!$P$1164
A8: 29 | B8: 3 | C8: АТ "БАНК АЛЬЯНС" | D8: 300119 | E8: =' 29АТ "БАНК АЛЬЯНС" '!$P$1139 | F8: =' 29АТ "БАНК АЛЬЯНС" '!$P$1138 | G8: =' 29АТ "БАНК АЛЬЯНС" '!$P$1150 | H8: =' 29АТ "БАНК АЛЬЯНС" '!$P$1148 | I8: =' 29АТ "БАНК АЛЬЯНС" '!$P$1149 | J8: =' 29АТ "БАНК АЛЬЯНС" '!$P$1144 | K8: =IFERROR(E8/J8*100,0) | L8: =IFERROR(E8/SUM(E6:E10)*100,0) | M8: =IFERROR((E8+F8)/J8*100,0) | N8: =IFERROR(F8/J8*100,0) | O8: =IFERROR(F8/SUM(F6:F10)*100,0) | P8: =' 29АТ "БАНК АЛЬЯНС" '!$J$1140 | Q8: =' 29АТ "БАНК АЛЬЯНС" '!$N$1141 | R8: =' 29АТ "БАНК АЛЬЯНС" '!$M$1142 | S8: =' 29АТ "БАНК АЛЬЯНС" '!$M$1143 | T8: =' 29АТ "БАНК АЛЬЯНС" '!$P$1151 | U8: =' 29АТ "БАНК АЛЬЯНС" '!$P$1152 | V8: =' 29АТ "БАНК АЛЬЯНС" '!$P$1154 | W8: =' 29АТ "БАНК АЛЬЯНС" '!$P$1155 | X8: =' 29АТ "БАНК АЛЬЯНС" '!$P$1156 | Y8: =' 29АТ "БАНК АЛЬЯНС" '!$P$1157 | Z8: =' 29АТ "БАНК АЛЬЯНС" '!$P$1158 | AA8: =' 29АТ "БАНК АЛЬЯНС" '!$P$1159 | AB8: =' 29АТ "БАНК АЛЬЯНС" '!$P$1160 | AC8: =' 29АТ "БАНК АЛЬЯНС" '!$P$1161 | AD8: =' 29АТ "БАНК АЛЬЯНС" '!$P$1162 | AE8: =' 29АТ "БАНК АЛЬЯНС" '!$P$1163 | AF8: =' 29АТ "БАНК АЛЬЯНС" '!$P$1164
A9: 36 | B9: 4 | C9: АТ "Райффайзен Банк" | D9: 300335 | E9: =' 36АТ "Райффайзен Банк" '!$P$1139 | F9: =' 36АТ "Райффайзен Банк" '!$P$1138 | G9: =' 36АТ "Райффайзен Банк" '!$P$1150 | H9: =' 36АТ "Райффайзен Банк" '!$P$1148 | I9: =' 36АТ "Райффайзен Банк" '!$P$1149 | J9: =' 36АТ "Райффайзен Банк" '!$P$1144 | K9: =IFERROR(E9/J9*100,0) | L9: =IFERROR(E9/SUM(E6:E10)*100,0) | M9: =IFERROR((E9+F9)/J9*100,0) | N9: =IFERROR(F9/J9*100,0) | O9: =IFERROR(F9/SUM(F6:F10)*100,0) | P9: =' 36АТ "Райффайзен Банк" '!$J$1140 | Q9: =' 36АТ "Райффайзен Банк" '!$N$1141 | R9: =' 36АТ "Райффайзен Банк" '!$M$1142 | S9: =' 36АТ "Райффайзен Банк" '!$M$1143 | T9: =' 36АТ "Райффайзен Банк" '!$P$1151 | U9: =' 36АТ "Райффайзен Банк" '!$P$1152 | V9: =' 36АТ "Райффайзен Банк" '!$P$1154 | W9: =' 36АТ "Райффайзен Банк" '!$P$1155 | X9: =' 36АТ "Райффайзен Банк" '!$P$1156 | Y9: =' 36АТ "Райффайзен Банк" '!$P$1157 | Z9: =' 36АТ "Райффайзен Банк" '!$P$1158 | AA9: =' 36АТ "Райффайзен Банк" '!$P$1159 | AB9: =' 36АТ "Райффайзен Банк" '!$P$1160 | AC9: =' 36АТ "Райффайзен Банк" '!$P$1161 | AD9: =' 36АТ "Райффайзен Банк" '!$P$1162 | AE9: =' 36АТ "Райффайзен Банк" '!$P$1163 | AF9: =' 36АТ "Райффайзен Банк" '!$P$1164
A10: 43 | B10: 5 | C10: АТ "АЛЬТБАНК" | D10: 320940 | E10: =' 43АТ "АЛЬТБАНК" '!$P$1139 | F10: =' 43АТ "АЛЬТБАНК" '!$P$1138 | G10: =' 43АТ "АЛЬТБАНК" '!$P$1150 | H10: =' 43АТ "АЛЬТБАНК" '!$P$1148 | I10: =' 43АТ "АЛЬТБАНК" '!$P$1149 | J10: =' 43АТ "АЛЬТБАНК" '!$P$1144 | K10: =IFERROR(E10/J10*100,0) | L10: =IFERROR(E10/SUM(E6:E10)*100,0) | M10: =IFERROR((E10+F10)/J10*100,0) | N10: =IFERROR(F10/J10*100,0) | O10: =IFERROR(F10/SUM(F6:F10)*100,0) | P10: =' 43АТ "АЛЬТБАНК" '!$J$1140 | Q10: =' 43АТ "АЛЬТБАНК" '!$N$1141 | R10: =' 43АТ "АЛЬТБАНК" '!$M$1142 | S10: =' 43АТ "АЛЬТБАНК" '!$M$1143 | T10: =' 43АТ "АЛЬТБАНК" '!$P$1151 | U10: =' 43АТ "АЛЬТБАНК" '!$P$1152 | V10: =' 43АТ "АЛЬТБАНК" '!$P$1154 | W10: =' 43АТ "АЛЬТБАНК" '!$P$1155 | X10: =' 43АТ "АЛЬТБАНК" '!$P$1156 | Y10: =' 43АТ "АЛЬТБАНК" '!$P$1157 | Z10: =' 43АТ "АЛЬТБАНК" '!$P$1158 | AA10: =' 43АТ "АЛЬТБАНК" '!$P$1159 | AB10: =' 43АТ "АЛЬТБАНК" '!$P$1160 | AC10: =' 43АТ "АЛЬТБАНК" '!$P$1161 | AD10: =' 43АТ "АЛЬТБАНК" '!$P$1162 | AE10: =' 43АТ "АЛЬТБАНК" '!$P$1163 | AF10: =' 43АТ "АЛЬТБАНК" '!$P$1164
A11: Всього | E11: =IFERROR(SUM(E6:E10),0) | F11: =IFERROR(SUM(F6:F10),0) | G11: =IFERROR(SUM(G6:G10),0) | H11: =IFERROR(SUM(H6:H10),0) | I11: =IFERROR(SUM(I6:I10),0) | J11: =IFERROR(SUM(J6:J10),0) | K11: =IFERROR(E11/J11*100,0) | L11: =IFERROR(E11/SUM(E6:E10)*100,0) | M11: =IFERROR((E11+F11)/J11*100,0) | N11: =IFERROR(F11/J11*100,0) | O11: =IFERROR(F11/SUM(F6:F10)*100,0) | P11: =IFERROR(SUM(P6:P10),0) | Q11: =IFERROR(SUM(Q6:Q10),0) | R11: =IFERROR(SUM(R6:R10),0) | S11: =IFERROR(SUM(S6:S10),0) | T11: =IFERROR(SUM(T6:T10),0) | U11: =IFERROR(SUM(U6:U10),0) | V11: =IFERROR(SUM(V6:V10),0) | W11: =IFERROR(SUM(W6:W10),0) | ... AF11: =IFERROR(SUM(AF6:AF10),0)
A12: Державні банки | E12: =IFERROR(SUM(E6,E7),0) | F12: =IFERROR(SUM(F6,F7),0) | G12: =IFERROR(SUM(G6,G7),0) | H12: =IFERROR(SUM(H6,H7),0) | I12: =IFERROR(SUM(I6,I7),0) | J12: =IFERROR(SUM(J6,J7),0) | K12: =IFERROR(E12/J12*100,0) | L12: =IFERROR(E12/E11*100,0) | M12: =IFERROR(SUM(M6,M7),0) | N12: =IFERROR(SUM(N6,N7),0) | O12: =IFERROR(F12/F11*100,0) | P12: =IFERROR(SUM(P6,P7),0) | Q12: =IFERROR(SUM(Q6,Q7),0) | R12: =IFERROR(SUM(R6,R7),0) | S12: =IFERROR(SUM(S6,S7),0) | T12: =IFERROR(SUM(T6,T7),0) | U12: =IFERROR(SUM(U6,U7),0) | V12: =IFERROR(SUM(V6,V7),0) | W12: =IFERROR(SUM(W6,W7),0) | ... AF12: =IFERROR(SUM(AF6,AF7),0)
A13: Банки з іноземним капіталом | E13: =IFERROR(SUM(E9),0) | F13: =IFERROR(SUM(F9),0) | G13: =IFERROR(SUM(G9),0) | H13: =IFERROR(SUM(H9),0) | I13: =IFERROR(SUM(I9),0) | J13: =IFERROR(SUM(J9),0) | K13: =IFERROR(E13/J13*100,0) | L13: =IFERROR(E13/E11*100,0) | M13: =IFERROR(SUM(M9),0) | N13: =IFERROR(SUM(N9),0) | O13: =IFERROR(F13/F11*100,0) | P13: =IFERROR(SUM(P9),0) | Q13: =IFERROR(SUM(Q9),0) | R13: =IFERROR(SUM(R9),0) | S13: =IFERROR(SUM(S9),0) | T13: =IFERROR(SUM(T9),0) | U13: =IFERROR(SUM(U9),0) | V13: =IFERROR(SUM(V9),0) | W13: =IFERROR(SUM(W9),0) | ... AF13: =IFERROR(SUM(AF9),0)
A14: Банки з українським приватним капіталом | E14: =IFERROR(E11-E12-E13,0) | F14: =IFERROR(F11-F12-F13,0) | G14: =IFERROR(G11-G12-G13,0) | H14: =IFERROR(H11-H12-H13,0) | I14: =IFERROR(I11-I12-I13,0) | J14: =IFERROR(J11-J12-J13,0) | K14: =IFERROR(E14/J14*100,0) | L14: =IFERROR(E14/E11*100,0) | M14: =IFERROR(M11-M12-M13,0) | N14: =IFERROR(N11-N12-N13,0) | O14: =IFERROR(F14/F11*100,0) | P14: =IFERROR(P11-P12-P13,0) | Q14: =IFERROR(Q11-Q12-Q13,0) | R14: =IFERROR(R11-R12-R13,0) | S14: =IFERROR(S11-S12-S13,0) | T14: =IFERROR(T11-T12-T13,0) | U14: =IFERROR(U11-U12-U13,0) | V14: =IFERROR(V11-V12-V13,0) | W14: =IFERROR(W11-W12-W13,0) | ... AF14: =IFERROR(AF11-AF12-AF13,0)
B16: Категорія | C16: ДС/ПД, % | H16: Категорія | I16: ДС до підсумку, %
B17: =A12 | C17: =IFERROR(K12,0) | H17: =A12 | I17: =IFERROR(L12,0)
B18: =A13 | C18: =IFERROR(K13,0) | H18: =A13 | I18: =IFERROR(L13,0)
B19: =A14 | C19: =IFERROR(K14,0) | H19: =A14 | I19: =IFERROR(L14,0)

Sheet Indicator_Summary
A1: ПРОЦЕНТНІ ДОХОДИ банків
B2: млрд | C2: %
A3: Депозитні сертифікати | B3: =SUM(Index!E6:E10)/1000000 | C3: =B3/B8 * 100
A4: ОВДП | B4: =SUM(Index!F6:F10)/1000000 | C4: =B4/B8 * 100
A5: Кредити бізнесу | B5: =SUM(Index!H6:H10)/1000000 | C5: =B5/B8 * 100
A6: Кредити населенню | B6: =SUM(Index!I6:I10)/1000000 | C6: =B6/B8 * 100
A7: Інші процентні доходи | B7: =B8 - (B3 +B4 +B5 +B6) | C7: =B7/B8 * 100
A8: ВСЬОГО | B8: =SUM(Index!J6:J10)/1000000 | C8: 100

Sheet Pivot_Data
A1: bank_code | B1: bank_name | C1: bank_class | D1: id | E1: indicator | F1: name | G1: category | H1: debit_total | I1: debit_nc | J1: debit_ic | K1: credit_total | L1: credit_nc | M1: credit_ic | N1: balance_total | O1: balance_nc | P1: balance_ic
A2: 2 | B2: АТ "Укрексімбанк" | C2: Державний | D2: 1001 | E2: (без привʼязки) | F2: Банкноти та монети в касі банку | G2: А | H2: 2881154.5 | I2: 1258377.3 | J2: 1622777.2 | K2: 2741564.6 | L2: 1220518.4 | M2: 1521046.2 | N2: 827366.58 | O2: 181416.63 | P2: 645949.94
A3: 2 | B3: АТ "Укрексімбанк" | C3: Державний | D3: 1002 | E3: (без привʼязки) | F3: Банкноти та монети в касі відділень банку | G3: А | H3: 421596.77 | I3: 177262.1 | J3: 244334.67 | K3: 420605.54 | L3: 178404.18 | M3: 242201.35 | N3: 68413.231 | O3: 15938.651 | P3: 52474.58
A4: 2 | B4: АТ "Укрексімбанк" | C4: Державний | D4: 1004 | E4: (без привʼязки) | F4: Банкноти та монети в банкоматах | G4: А | H4: 1424777.4 | I4: 1424777.4 | J4: 0 | K4: 1427186.2 | L4: 1427186.2 | M4: 0 | N4: 345970.89 | O4: 345970.89 | P4: 0
A5: 2 | B5: АТ "Укрексімбанк" | C5: Державний | D5: 1005 | E5: (без привʼязки) | F5: Банкноти та монети, інкасовані до перерахування | G5: А | H5: 94970.078 | I5: 94970.078 | J5: 0 | K5: 94970.078 | L5: 94970.078 | M5: 0 | N5: 0 | O5: 0 | P5: 0
A6: 2 | B6: АТ "Укрексімбанк" | C6: Державний | D6: 1006 | E6: (без привʼязки) | F6: Банкноти та монети на зберіганні в інкасаторській компанії | G6: А | H6: 0 | I6: 0 | J6: 0 | K6: 0 | L6: 0 | M6: 0 | N6: 0 | O6: 0 | P6: 0
A7: 2 | B7: АТ "Укрексімбанк" | C7: Державний | D7: 1007 | E7: (без привʼязки) | F7: Банкноти та монети в дорозі | G7: А | H7: 880991.48 | I7: 256979.65 | J7: 624011.83 | K7: 911560.8 | L7: 261956.45 | M7: 649604.35 | N7: 0 | O7: 0 | P7: 0
A8: 2 | B8: АТ "Укрексімбанк" | C8: Державний | D8: 1011 | E8: (без привʼязки) | F8: Дорожні чеки в касі банку | G8: А | H8: 0 | I8: 0 | J8: 0 | K8: 0 | L8: 0 | M8: 0 | N8: 0 | O8: 0 | P8: 0
A9: 2 | B9: АТ "Укрексімбанк" | C9: Державний | D9: 1012 | E9: (без привʼязки) | F9: Дорожні чеки в касі відділень банку | G9: А | H9: 0 | I9: 0 | J9: 0 | K9: 0 | L9: 0 | M9: 0 | N9: 0 | O9: 0 | P9: 0
A10: 2 | B10: АТ "Укрексімбанк" | C10: Державний | D10: 1090 | E10: (без привʼязки) | F10: Резерви за готівковими коштами, наявність яких є непідтвердженою | G10: П | H10: 533.62252 | I10: 0 | J10: 533.62252 | K10: 785.03309 | L10: 0 | M10: 785.03309 | N10: -50810.589 | O10: -5377.8999 | P10: -45432.689
A11: 2 | B11: АТ "Укрексімбанк" | C11: Державний | D11: 1101 | E11: (без привʼязки) | F11: Банківські метали в банку | G11: А | H11: 0 | I11: 0 | J11: 0 | K11: 0 | L11: 0 | M11: 0 | N11: 0 | O11: 0 | P11: 0
A12: 2 | B12: АТ "Укрексімбанк" | C12: Державний | D12: 1102 | E12: (без привʼязки) | F12: Банківські метали у відділенні банку | G12: А | H12: 0 | I12: 0 | J12: 0 | K12: 0 | L12: 0 | M12: 0 | N12: 0 | O12: 0 | P12: 0
A13: 2 | B13: АТ "Укрексімбанк" | C13: Державний | D13: 1107 | E13: (без привʼязки) | F13: Банківські метали в дорозі | G13: А | H13: 0 | I13: 0 | J13: 0 | K13: 0 | L13: 0 | M13: 0 | N13: 0 | O13: 0 | P13: 0
... A6516: 43 | B6516: АТ "АЛЬТБАНК" | C6516: Приватний капітал | D6516: 9916 | E6516: (без привʼязки) | F6516: 0 | G6516: П | H6516: 0 | I6516: 0 | J6516: 0 | K6516: 0 | L6516: 0 | M6516: 0 | N6516: 0 | O6516: 0 | P6516: 0

Sheet Зміст
B2: Оборотно-сальдовий баланс банку | C2: відповідно до підпункту 1 пункту 2 постанови Правління Національного банку України
C3: від 15 березня 2018 року № 11 “Про встановлення переліку інформації, що підлягає обов'язковому опублікуванню банками України” (зі змінами)
C4: за даними статистичної звітності з файлу 02X “Дані про обороти та залишки на рахунках”.
A6: NKB | B6: Назва | C6: МФО
A7: 2 | B7: АТ "Укрексімбанк" | C7: 322313
A8: 6 | B8: АТ "ОЩАДБАНК" | C8: 300465
A9: 29 | B9: АТ "БАНК АЛЬЯНС" | C9: 300119
A10: 36 | B10: АТ "Райффайзен Банк" | C10: 300335
A11: 43 | B11: АТ "АЛЬТБАНК" | C11: 320940
A12: 46 | B12: АТ КБ "ПриватБанк" | C12: 305299
A13: 49 | B13: Полікомбанк | C13: 353100
A14: 62 | B14: АТ "ТАСКОМБАНК" | C14: 339500
A15: 72 | B15: ПрАТ "БАНК ФАМІЛЬНИЙ" | C15: 334840
A16: 88 | B16: АТ "КРЕДОБАНК" | C16: 325365
A17: 91 | B17: АТ АКБ "Львів" | C17: 325268
... A66: 774 | B66: АТ "РВС БАНК"* | C66: 339072
A68: * Неплатоспроможний банк.

Sheet   2АТ "Укрексімбанк" 
A1: Зміст
B2: Оборотно-сальдовий баланс банку АТ "Укрексімбанк" за станом на 01.12.2025
B3: (тис грн)
A4: Номер з/п | B4: Клас/ розділ/ група/ рахунок | I4: Актив/ пасив | J4: Обороти за місяць | Q4: Сальдо
J5: дебет | M5: кредит | Q5: усього | R5: НВ | S5: ІВ
B6: номер | F6: назва | J6: усього | K6: НВ | L6: ІВ | M6: усього | O6: НВ | P6: ІВ
A7: 1 | B7: 2 | F7: 3 | I7: 4 | J7: 5 | K7: 6 | L7: 7 | M7: 8 | O7: 9 | P7: 10 | Q7: 11 | R7: 12 | S7: 13
A8: 1 | B8: Балансові рахунки
A9: 2 | B9: Активи
A10: 3 | B10: Класи 1 - 4
A11: 4 | B11: Клас 1 | C11: 10 | D11: 100 | F11: 1001 | H11: Банкноти та монети в касі банку | I11: А | J11: 2881154.5 | K11: 1258377.3 | L11: 1622777.2 | M11: 2741564.6 | O11: 1220518.4 | P11: 1521046.2 | Q11: 827366.58 | R11: 181416.63 | S11: 645949.94
A12: 5 | F12: 1002 | H12: Банкноти та монети в касі відділень банку | I12: А | J12: 421596.77 | K12: 177262.1 | L12: 244334.67 | M12: 420605.54 | O12: 178404.18 | P12: 242201.35 | Q12: 68413.231 | R12: 15938.651 | S12: 52474.58
A13: 6 | F13: 1004 | H13: Банкноти та монети в банкоматах | I13: А | J13: 1424777.4 | K13: 1424777.4 | L13: 0 | M13: 1427186.2 | O13: 1427186.2 | P13: 0 | Q13: 345970.89 | R13: 345970.89 | S13: 0
A14: 7 | F14: 1005 | H14: Банкноти та монети, інкасовані до перерахування | I14: А | J14: 94970.078 | K14: 94970.078 | L14: 0 | M14: 94970.078 | O14: 94970.078 | P14: 0 | Q14: 0 | R14: 0 | S14: 0
A15: 8 | F15: 1006 | H15: Банкноти та монети на зберіганні в інкасаторській компанії | I15: А | J15: 0 | K15: 0 | L15: 0 | M15: 0 | O15: 0 | P15: 0 | Q15: 0 | R15: 0 | S15: 0
A16: 9 | F16: 1007 | H16: Банкноти та монети в дорозі | I16: А | J16: 880991.48 | K16: 256979.65 | L16: 624011.83 | M16: 911560.8 | O16: 261956.45 | P16: 649604.35 | Q16: 0 | R16: 0 | S16: 0
A17: 10 | F17: Група 100 - Усього | J17: 5703490.3 | K17: 3212366.5 | L17: 2491123.7 | M17: 5595887.3 | O17: 3183035.4 | P17: 2412851.9 | Q17: 1241750.7 | R17: 543326.17 | S17: 698424.52
A18: 11 | D18: 101 | F18: 1011 | H18: Дорожні чеки в касі банку | I18: А | J18: 0 | K18: 0 | L18: 0 | M18: 0 | O18: 0 | P18: 0 | Q18: 0 | R18: 0 | S18: 0
A19: 12 | F19: 1012 | H19: Дорожні чеки в касі відділень банку | I19: А | J19: 0 | K19: 0 | L19: 0 | M19: 0 | O19: 0 | P19: 0 | Q19: 0 | R19: 0 | S19: 0
A20: 13 | F20: Група 101 - Усього | J20: 0 | K20: 0 | L20: 0 | M20: 0 | O20: 0 | P20: 0 | Q20: 0 | R20: 0 | S20: 0
A21: 14 | D21: 109 | F21: 1090 | H21: Резерви за готівковими коштами, наявність яких є непідтвердженою | I21: П | J21: 533.62252 | K21: 0 | L21: 533.62252 | M21: 785.03309 | O21: 0 | P21: 785.03309 | Q21: -50810.589 | R21: -5377.8999 | S21: -45432.689
A22: 15 | F22: Група 109 - Усього | J22: 533.62252 | K22: 0 | L22: 533.62252 | M22: 785.03309 | O22: 0 | P22: 785.03309 | Q22: -50810.589 | R22: -5377.8999 | S22: -45432.689
A23: 16 | D23: Розділ 10 - Усього | J23: 5704023.9 | K23: 3212366.5 | L23: 2491657.3 | M23: 5596672.3 | O23: 3183035.4 | P23: 2413636.9 | Q23: 1190940.1 | R23: 537948.27 | S23: 652991.84
A24: 17 | C24: 11 | D24: 110 | F24: 1101 | H24: Банківські метали в банку | I24: А | J24: 0 | K24: 0 | L24: 0 | M24: 0 | O24: 0 | P24: 0 | Q24: 0 | R24: 0 | S24: 0
A25: 18 | F25: 1102 | H25: Банківські метали у відділенні банку | I25: А | J25: 0 | K25: 0 | L25: 0 | M25: 0 | O25: 0 | P25: 0 | Q25: 0 | R25: 0 | S25: 0
A26: 19 | F26: 1107 | H26: Банківські метали в дорозі | I26: А | J26: 0 | K26: 0 | L26: 0 | M26: 0 | O26: 0 | P26: 0 | Q26: 0 | R26: 0 | S26: 0
A27: 20 | F27: Група 110 - Усього | J27: 0 | K27: 0 | L27: 0 | M27: 0 | O27: 0 | P27: 0 | Q27: 0 | R27: 0 | S27: 0
A28: 21 | D28: 119 | F28: 1190 | H28: Резерви за банківськими металами, наявність яких є непідтвердженою | I28: П | J28: 0 | K28: 0 | L28: 0 | M28: 0 | O28: 0 | P28: 0 | Q28: 0 | R28: 0 | S28: 0
A29: 22 | F29: Група 119 - Усього | J29: 0 | K29: 0 | L29: 0 | M29: 0 | O29: 0 | P29: 0 | Q29: 0 | R29: 0 | S29: 0
A30: 23 | D30: Розділ 11 - Усього | J30: 0 | K30: 0 | L30: 0 | M30: 0 | O30: 0 | P30: 0 | Q30: 0 | R30: 0 | S30: 0
A31: 24 | C31: 12 | D31: 120 | F31: 1200 | H31: Кореспондентський рахунок банку в Національному банку України | I31: А | J31: 5.6606691e+08 | K31: 5.6606691e+08 | L31: 0 | M31: 5.616171e+08 | O31: 5.616171e+08 | P31: 0 | Q31: 22042210 | R31: 22042210 | S31: 0
A32: 25 | F32: 1202 | H32: Кошти банків за рахунками умовного зберігання (ескроу) у Національному банку України | I32: А | J32: 0 | K32: 0 | L32: 0 | M32: 0 | O32: 0 | P32: 0 | Q32: 0 | R32: 0 | S32: 0
A33: 26 | F33: 1205 | H33: Кошти банків для забезпечення виконання зобов’язань перед Національним банком України за кредитами, наданими банкам, та операціями своп процентної ставки | I33: А | J33: 0 | K33: 0 | L33: 0 | M33: 0 | O33: 0 | P33: 0 | Q33: 0 | R33: 0 | S33: 0
A34: 27 | F34: 1208 | H34: Нараховані доходи за коштами на вимогу в Національному банку України | I34: А | J34: 0 | K34: 0 | L34: 0 | M34: 0 | O34: 0 | P34: 0 | Q34: 0 | R34: 0 | S34: 0
A35: 28 | F35: Група 120 - Усього | J35: 5.6606691e+08 | K35: 5.6606691e+08 | L35: 0 | M35: 5.616171e+08 | O35: 5.616171e+08 | P35: 0 | Q35: 22042210 | R35: 22042210 | S35: 0
A36: 29 | D36: Розділ 12 - Усього | J36: 5.6606691e+08 | K36: 5.6606691e+08 | L36: 0 | M36: 5.616171e+08 | O36: 5.616171e+08 | P36: 0 | Q36: 22042210 | R36: 22042210 | S36: 0
A37: 30 | C37: 14 | D37: 140 | F37: 1400 | H37: Облігації внутрішньої державної позики, що рефінансуються Національним банком України, які обліковуються за справедливою вартістю через прибутки/збитки | I37: А | J37: 9461457.4 | K37: 5951813 | L37: 3509644.4 | M37: 12068323 | O37: 8995306 | P37: 3073017.2 | Q37: 13863168 | R37: 13246549 | S37: 616618.88
A38: 31 | F38: 1405 | H38: Переоцінка боргових цінних паперів, що рефінансуються Національним банком України, які обліковуються за справедливою вартістю через прибутки/збитки | I38: А | J38: 374584.69 | K38: 372410.19 | L38: 2174.4995 | M38: 2627750.8 | O38: 2625165.2 | P38: 2585.535 | Q38: 6054103.6 | R38: 6053531 | S38: 572.58176
A39: 32 | I39: П | J39: 0 | K39: 0 | L39: 0 | M39: 0 | O39: 0 | P39: 0 | Q39: -57653.272 | R39: -57281.832 | S39: -371.44051
A40: 33 | F40: 1406 | H40: Неамортизована премія/дисконт за борговими цінними паперами, що рефінансуються Національним банком України, які обліковуються за справедливою вартістю через прибутки/збитки | I40: А | J40: 76966.686 | K40: 72049.045 | L40: 4917.6409 | M40: 60453.482 | O40: 56658.297 | P40: 3795.1846 | Q40: 704401.07 | R40: 703238.51 | S40: 1162.5606
...

Sheet   6АТ "Ощадбанк" 
A1: Зміст
B2: Оборотно-сальдовий баланс банку АТ "Ощадбанк" за станом на 01.12.2025
B3: (тис грн)
A4: Номер з/п | B4: Клас/ розділ/ група/ рахунок | I4: Актив/ пасив | J4: Обороти за місяць | Q4: Сальдо
J5: дебет | M5: кредит | Q5: усього | R5: НВ | S5: ІВ
B6: номер | F6: назва | J6: усього | K6: НВ | L6: ІВ | M6: усього | O6: НВ | P6: ІВ
A7: 1 | B7: 2 | F7: 3 | I7: 4 | J7: 5 | K7: 6 | L7: 7 | M7: 8 | O7: 9 | P7: 10 | Q7: 11 | R7: 12 | S7: 13
A8: 1 | B8: Балансові рахунки
A9: 2 | B9: Активи
A10: 3 | B10: Класи 1 - 4
A11: 4 | B11: Клас 1 | C11: 10 | D11: 100 | F11: 1001 | H11: Банкноти та монети в касі банку | I11: А | J11: 3.4685127e+08 | K11: 2.4845102e+08 | L11: 98400245 | M11: 3.5018686e+08 | O11: 2.4865152e+08 | P11: 1.0153534e+08 | Q11: 11370724 | R11: 4710103.9 | S11: 6660620.3
A12: 5 | F12: 1002 | H12: Банкноти та монети в касі відділень банку | I12: А | J12: 31969781 | K12: 22111338 | L12: 9858442.6 | M12: 31953367 | O12: 22110933 | P12: 9842434.8 | Q12: 1614023.6 | R12: 1006363.3 | S12: 607660.37
A13: 6 | F13: 1004 | H13: Банкноти та монети в банкоматах | I13: А | J13: 29224510 | K13: 29224510 | L13: 0 | M13: 29744829 | O13: 29744829 | P13: 0 | Q13: 3450082.5 | R13: 3450082.5 | S13: 0
A14: 7 | F14: 1005 | H14: Банкноти та монети, інкасовані до перерахування | I14: А | J14: 47127459 | K14: 47127459 | L14: 0 | M14: 47127459 | O14: 47127459 | P14: 0 | Q14: 0 | R14: 0 | S14: 0
A15: 8 | F15: 1006 | H15: Банкноти та монети на зберіганні в інкасаторській компанії | I15: А | J15: 0 | K15: 0 | L15: 0 | M15: 0 | O15: 0 | P15: 0 | Q15: 0 | R15: 0 | S15: 0
A16: 9 | F16: 1007 | H16: Банкноти та монети в дорозі | I16: А | J16: 1.4916987e+08 | K16: 1.0183119e+08 | L16: 47338684 | M16: 1.4921505e+08 | O16: 1.0185275e+08 | P16: 47362306 | Q16: 56256.937 | R16: 39168.454 | S16: 17088.483
A17: 10 | F17: Група 100 - Усього | J17: 6.0434289e+08 | K17: 4.4874552e+08 | L17: 1.5559737e+08 | M17: 6.0822757e+08 | O17: 4.4948749e+08 | P17: 1.5874008e+08 | Q17: 16491087 | R17: 9205718.1 | S17: 7285369.1
A18: 11 | D18: 101 | F18: 1011 | H18: Дорожні чеки в касі банку | I18: А | J18: 0 | K18: 0 | L18: 0 | M18: 0 | O18: 0 | P18: 0 | Q18: 0 | R18: 0 | S18: 0
A19: 12 | F19: 1012 | H19: Дорожні чеки в касі відділень банку | I19: А | J19: 0 | K19: 0 | L19: 0 | M19: 0 | O19: 0 | P19: 0 | Q19: 0 | R19: 0 | S19: 0
A20: 13 | F20: Група 101 - Усього | J20: 0 | K20: 0 | L20: 0 | M20: 0 | O20: 0 | P20: 0 | Q20: 0 | R20: 0 | S20: 0
A21: 14 | D21: 109 | F21: 1090 | H21: Резерви за готівковими коштами, наявність яких є непідтвердженою | I21: П | J21: 237.41988 | K21: 0 | L21: 237.41988 | M21: 355.90706 | O21: 0 | P21: 355.90706 | Q21: -95002.152 | R21: -73346.687 | S21: -21655.464
A22: 15 | F22: Група 109 - Усього | J22: 237.41988 | K22: 0 | L22: 237.41988 | M22: 355.90706 | O22: 0 | P22: 355.90706 | Q22: -95002.152 | R22: -73346.687 | S22: -21655.464
A23: 16 | D23: Розділ 10 - Усього | J23: 6.0434313e+08 | K23: 4.4874552e+08 | L23: 1.5559761e+08 | M23: 6.0822792e+08 | O23: 4.4948749e+08 | P23: 1.5874043e+08 | Q23: 16396085 | R23: 9132371.4 | S23: 7263713.6
A24: 17 | C24: 11 | D24: 110 | F24: 1101 | H24: Банківські метали в банку | I24: А | J24: 353637.25 | K24: 0 | L24: 353637.25 | M24: 350748.1 | O24: 0 | P24: 350748.1 | Q24: 55025.842 | R24: 0 | S24: 55025.842
A25: 18 | F25: 1102 | H25: Банківські метали у відділенні банку | I25: А | J25: 7770.1245 | K25: 0 | L25: 7770.1245 | M25: 10121.918 | O25: 0 | P25: 10121.918 | Q25: 19871.401 | R25: 0 | S25: 19871.401
A26: 19 | F26: 1107 | H26: Банківські метали в дорозі | I26: А | J26: 11032.816 | K26: 0 | L26: 11032.816 | M26: 11032.816 | O26: 0 | P26: 11032.816 | Q26: 0 | R26: 0 | S26: 0
A27: 20 | F27: Група 110 - Усього | J27: 372440.19 | K27: 0 | L27: 372440.19 | M27: 371902.84 | O27: 0 | P27: 371902.84 | Q27: 74897.243 | R27: 0 | S27: 74897.243
A28: 21 | D28: 119 | F28: 1190 | H28: Резерви за банківськими металами, наявність яких є непідтвердженою | I28: П | J28: 141.65131 | K28: 0 | L28: 141.65131 | M28: 238.78803 | O28: 0 | P28: 238.78803 | Q28: -1517.55 | R28: 0 | S28: -1517.55
A29: 22 | F29: Група 119 - Усього | J29: 141.65131 | K29: 0 | L29: 141.65131 | M29: 238.78803 | O29: 0 | P29: 238.78803 | Q29: -1517.55 | R29: 0 | S29: -1517.55
A30: 23 | D30: Розділ 11 - Усього | J30: 372581.84 | K30: 0 | L30: 372581.84 | M30: 372141.62 | O30: 0 | P30: 372141.62 | Q30: 73379.693 | R30: 0 | S30: 73379.693
A31: 24 | C31: 12 | D31: 120 | F31: 1200 | H31: Кореспондентський рахунок банку в Національному банку України | I31: А | J31: 1.0789626e+09 | K31: 1.0789626e+09 | L31: 0 | M31: 1.0803335e+09 | O31: 1.0803335e+09 | P31: 0 | Q31: 27081639 | R31: 27081639 | S31: 0
A32: 25 | F32: 1202 | H32: Кошти банків за рахунками умовного зберігання (ескроу) у Національному банку України | I32: А | J32: 3329.2404 | K32: 0 | L32: 3329.2404 | M32: 14823.453 | O32: 0 | P32: 14823.453 | Q32: 215803.38 | R32: 8000 | S32: 207803.38
A33: 26 | F33: 1205 | H33: Кошти банків для забезпечення виконання зобов’язань перед Національним банком України за кредитами, наданими банкам, та операціями своп процентної ставки | I33: А | J33: 0 | K33: 0 | L33: 0 | M33: 0 | O33: 0 | P33: 0 | Q33: 0 | R33: 0 | S33: 0
A34: 27 | F34: 1208 | H34: Нараховані доходи за коштами на вимогу в Національному банку України | I34: А | J34: 811.15567 | K34: 0 | L34: 811.15567 | M34: 811.15567 | O34: 0 | P34: 811.15567 | Q34: 0 | R34: 0 | S34: 0
A35: 28 | F35: Група 120 - Усього | J35: 1.0789667e+09 | K35: 1.0789626e+09 | L35: 4140.3961 | M35: 1.0803491e+09 | O35: 1.0803335e+09 | P35: 15634.608 | Q35: 27297443 | R35: 27089639 | S35: 207803.38
A36: 29 | D36: Розділ 12 - Усього | J36: 1.0789667e+09 | K36: 1.0789626e+09 | L36: 4140.3961 | M36: 1.0803491e+09 | O36: 1.0803335e+09 | P36: 15634.608 | Q36: 27297443 | R36: 27089639 | S36: 207803.38
A37: 30 | C37: 14 | D37: 140 | F37: 1400 | H37: Облігації внутрішньої державної позики, що рефінансуються Національним банком України, які обліковуються за справедливою вартістю через прибутки/збитки | I37: А | J37: 402056.77 | K37: 76007 | L37: 326049.77 | M37: 2679493.6 | O37: 2465739 | P37: 213754.59 | Q37: 9443620.9 | R37: 9299484 | S37: 144136.92
A38: 31 | F38: 1405 | H38: Переоцінка боргових цінних паперів, що рефінансуються Національним банком України, які обліковуються за справедливою вартістю через прибутки/збитки | I38: А | J38: 23052699 | K38: 23044353 | L38: 8346.2078 | M38: 24877155 | O38: 24868699 | P38: 8456.1116 | Q38: 6439810.9 | R38: 6439610.5 | S38: 200.37088
A39: 32 | I39: П | J39: 0 | K39: 0 | L39: 0 | M39: 0 | O39: 0 | P39: 0 | Q39: -1020862.9 | R39: -1020455.3 | S39: -407.55967
A40: 33 | F40: 1406 | H40: Неамортизована премія/дисконт за борговими цінними паперами, що рефінансуються Національним банком України, які обліковуються за справедливою вартістю через прибутки/збитки | I40: А | J40: 25594.433 | K40: 25481.393 | L40: 113.03955 | M40: 152.61538 | O40: 28.25133 | P40: 124.36405 | Q40: 18.27385 | R40: 18.27385 | S40: 0
...

Sheet  29АТ "БАНК АЛЬЯНС" 
A1: Зміст
B2: Оборотно-сальдовий баланс банку АТ "БАНК АЛЬЯНС" за станом на 01.12.2025
B3: (тис грн)
A4: Номер з/п | B4: Клас/ розділ/ група/ рахунок | I4: Актив/ пасив | J4: Обороти за місяць | Q4: Сальдо
J5: дебет | M5: кредит | Q5: усього | R5: НВ | S5: ІВ
B6: номер | F6: назва | J6: усього | K6: НВ | L6: ІВ | M6: усього | O6: НВ | P6: ІВ
A7: 1 | B7: 2 | F7: 3 | I7: 4 | J7: 5 | K7: 6 | L7: 7 | M7: 8 | O7: 9 | P7: 10 | Q7: 11 | R7: 12 | S7: 13
A8: 1 | B8: Балансові рахунки
A9: 2 | B9: Активи
A10: 3 | B10: Класи 1 - 4
A11: 4 | B11: Клас 1 | C11: 10 | D11: 100 | F11: 1001 | H11: Банкноти та монети в касі банку | I11: А | J11: 0 | K11: 0 | L11: 0 | M11: 0 | O11: 0 | P11: 0 | Q11: 0 | R11: 0 | S11: 0
A12: 5 | F12: 1002 | H12: Банкноти та монети в касі відділень банку | I12: А | J12: 2593930.3 | K12: 1334258.6 | L12: 1259671.7 | M12: 2598171.3 | O12: 1369257 | P12: 1228914.4 | Q12: 334285.1 | R12: 261019.39 | S12: 73265.712
A13: 6 | F13: 1004 | H13: Банкноти та монети в банкоматах | I13: А | J13: 706213.23 | K13: 370477.18 | L13: 335736.05 | M13: 686788.71 | O13: 345935.06 | P13: 340853.65 | Q13: 60657.867 | R13: 40737.359 | S13: 19920.508
A14: 7 | F14: 1005 | H14: Банкноти та монети, інкасовані до перерахування | I14: А | J14: 10646.788 | K14: 10646.788 | L14: 0 | M14: 10646.788 | O14: 10646.788 | P14: 0 | Q14: 0 | R14: 0 | S14: 0
A15: 8 | F15: 1006 | H15: Банкноти та монети на зберіганні в інкасаторській компанії | I15: А | J15: 0 | K15: 0 | L15: 0 | M15: 0 | O15: 0 | P15: 0 | Q15: 0 | R15: 0 | S15: 0
A16: 9 | F16: 1007 | H16: Банкноти та монети в дорозі | I16: А | J16: 865633.92 | K16: 461294.02 | L16: 404339.9 | M16: 865633.92 | O16: 461294.02 | P16: 404339.9 | Q16: 0 | R16: 0 | S16: 0
A17: 10 | F17: Група 100 - Усього | J17: 4176424.2 | K17: 2176676.6 | L17: 1999747.7 | M17: 4161240.8 | O17: 2187132.8 | P17: 1974107.9 | Q17: 394942.97 | R17: 301756.75 | S17: 93186.219
A18: 11 | D18: 101 | F18: 1011 | H18: Дорожні чеки в касі банку | I18: А | J18: 0 | K18: 0 | L18: 0 | M18: 0 | O18: 0 | P18: 0 | Q18: 0 | R18: 0 | S18: 0
A19: 12 | F19: 1012 | H19: Дорожні чеки в касі відділень банку | I19: А | J19: 0 | K19: 0 | L19: 0 | M19: 0 | O19: 0 | P19: 0 | Q19: 0 | R19: 0 | S19: 0
A20: 13 | F20: Група 101 - Усього | J20: 0 | K20: 0 | L20: 0 | M20: 0 | O20: 0 | P20: 0 | Q20: 0 | R20: 0 | S20: 0
A21: 14 | D21: 109 | F21: 1090 | H21: Резерви за готівковими коштами, наявність яких є непідтвердженою | I21: П | J21: 0 | K21: 0 | L21: 0 | M21: 0 | O21: 0 | P21: 0 | Q21: 0 | R21: 0 | S21: 0
A22: 15 | F22: Група 109 - Усього | J22: 0 | K22: 0 | L22: 0 | M22: 0 | O22: 0 | P22: 0 | Q22: 0 | R22: 0 | S22: 0
A23: 16 | D23: Розділ 10 - Усього | J23: 4176424.2 | K23: 2176676.6 | L23: 1999747.7 | M23: 4161240.8 | O23: 2187132.8 | P23: 1974107.9 | Q23: 394942.97 | R23: 301756.75 | S23: 93186.219
A24: 17 | C24: 11 | D24: 110 | F24: 1101 | H24: Банківські метали в банку | I24: А | J24: 0 | K24: 0 | L24: 0 | M24: 0 | O24: 0 | P24: 0 | Q24: 0 | R24: 0 | S24: 0
A25: 18 | F25: 1102 | H25: Банківські метали у відділенні банку | I25: А | J25: 10979.895 | K25: 0 | L25: 10979.895 | M25: 5905.9972 | O25: 0 | P25: 5905.9972 | Q25: 5073.8979 | R25: 0 | S25: 5073.8979
A26: 19 | F26: 1107 | H26: Банківські метали в дорозі | I26: А | J26: 5012.4947 | K26: 0 | L26: 5012.4947 | M26: 5012.4947 | O26: 0 | P26: 5012.4947 | Q26: 0 | R26: 0 | S26: 0
A27: 20 | F27: Група 110 - Усього | J27: 15992.39 | K27: 0 | L27: 15992.39 | M27: 10918.492 | O27: 0 | P27: 10918.492 | Q27: 5073.8979 | R27: 0 | S27: 5073.8979
A28: 21 | D28: 119 | F28: 1190 | H28: Резерви за банківськими металами, наявність яких є непідтвердженою | I28: П | J28: 0 | K28: 0 | L28: 0 | M28: 0 | O28: 0 | P28: 0 | Q28: 0 | R28: 0 | S28: 0
A29: 22 | F29: Група 119 - Усього | J29: 0 | K29: 0 | L29: 0 | M29: 0 | O29: 0 | P29: 0 | Q29: 0 | R29: 0 | S29: 0
A30: 23 | D30: Розділ 11 - Усього | J30: 15992.39 | K30: 0 | L30: 15992.39 | M30: 10918.492 | O30: 0 | P30: 10918.492 | Q30: 5073.8979 | R30: 0 | S30: 5073.8979
A31: 24 | C31: 12 | D31: 120 | F31: 1200 | H31: Кореспондентський рахунок банку в Національному банку України | I31: А | J31: 68964021 | K31: 68964021 | L31: 0 | M31: 69354428 | O31: 69354428 | P31: 0 | Q31: 193019.52 | R31: 193019.52 | S31: 0
A32: 25 | F32: 1202 | H32: Кошти банків за рахунками умовного зберігання (ескроу) у Національному банку України | I32: А | J32: 0 | K32: 0 | L32: 0 | M32: 0 | O32: 0 | P32: 0 | Q32: 0 | R32: 0 | S32: 0
A33: 26 | F33: 1205 | H33: Кошти банків для забезпечення виконання зобов’язань перед Національним банком України за кредитами, наданими банкам, та операціями своп процентної ставки | I33: А | J33: 0 | K33: 0 | L33: 0 | M33: 0 | O33: 0 | P33: 0 | Q33: 0 | R33: 0 | S33: 0
A34: 27 | F34: 1208 | H34: Нараховані доходи за коштами на вимогу в Національному банку України | I34: А | J34: 0 | K34: 0 | L34: 0 | M34: 0 | O34: 0 | P34: 0 | Q34: 0 | R34: 0 | S34: 0
A35: 28 | F35: Група 120 - Усього | J35: 68964021 | K35: 68964021 | L35: 0 | M35: 69354428 | O35: 69354428 | P35: 0 | Q35: 193019.52 | R35: 193019.52 | S35: 0
A36: 29 | D36: Розділ 12 - Усього | J36: 68964021 | K36: 68964021 | L36: 0 | M36: 69354428 | O36: 69354428 | P36: 0 | Q36: 193019.52 | R36: 193019.52 | S36: 0
A37: 30 | C37: 14 | D37: 140 | F37: 1400 | H37: Облігації внутрішньої державної позики, що рефінансуються Національним банком України, які обліковуються за справедливою вартістю через прибутки/збитки | I37: А | J37: 0 | K37: 0 | L37: 0 | M37: 0 | O37: 0 | P37: 0 | Q37: 0 | R37: 0 | S37: 0
A38: 31 | F38: 1405 | H38: Переоцінка боргових цінних паперів, що рефінансуються Національним банком України, які обліковуються за справедливою вартістю через прибутки/збитки | I38: А | J38: 0 | K38: 0 | L38: 0 | M38: 0 | O38: 0 | P38: 0 | Q38: 0 | R38: 0 | S38: 0
A39: 32 | I39: П | J39: 0 | K39: 0 | L39: 0 | M39: 0 | O39: 0 | P39: 0 | Q39: 0 | R39: 0 | S39: 0
A40: 33 | F40: 1406 | H40: Неамортизована премія/дисконт за борговими цінними паперами, що рефінансуються Національним банком України, які обліковуються за справедливою вартістю через прибутки/збитки | I40: А | J40: 0 | K40: 0 | L40: 0 | M40: 0 | O40: 0 | P40: 0 | Q40: 0 | R40: 0 | S40: 0
...

Sheet  36АТ "Райффайзен Банк" 
A1: Зміст
B2: Оборотно-сальдовий баланс банку АТ "Райффайзен Банк" за станом на 01.12.2025
B3: (тис грн)
A4: Номер з/п | B4: Клас/ розділ/ група/ рахунок | I4: Актив/ пасив | J4: Обороти за місяць | Q4: Сальдо
J5: дебет | M5: кредит | Q5: усього | R5: НВ | S5: ІВ
B6: номер | F6: назва | J6: усього | K6: НВ | L6: ІВ | M6: усього | O6: НВ | P6: ІВ
A7: 1 | B7: 2 | F7: 3 | I7: 4 | J7: 5 | K7: 6 | L7: 7 | M7: 8 | O7: 9 | P7: 10 | Q7: 11 | R7: 12 | S7: 13
A8: 1 | B8: Балансові рахунки
A9: 2 | B9: Активи
A10: 3 | B10: Класи 1 - 4
A11: 4 | B11: Клас 1 | C11: 10 | D11: 100 | F11: 1001 | H11: Банкноти та монети в касі банку | I11: А | J11: 32101678 | K11: 19820331 | L11: 12281347 | M11: 32555007 | O11: 20202094 | P11: 12352912 | Q11: 3352158 | R11: 1450726.7 | S11: 1901431.3
A12: 5 | F12: 1002 | H12: Банкноти та монети в касі відділень банку | I12: А | J12: 65058428 | K12: 29868817 | L12: 35189611 | M12: 64695342 | O12: 29589444 | P12: 35105898 | Q12: 4828600.7 | R12: 2718764.2 | S12: 2109836.5
A13: 6 | F13: 1004 | H13: Банкноти та монети в банкоматах | I13: А | J13: 19924497 | K13: 19818088 | L13: 106409.6 | M13: 20298249 | O13: 20187663 | P13: 110585.91 | Q13: 2484330.1 | R13: 2443379.2 | S13: 40950.874
A14: 7 | F14: 1005 | H14: Банкноти та монети, інкасовані до перерахування | I14: А | J14: 1421319.3 | K14: 1421319.3 | L14: 0 | M14: 1421319.3 | O14: 1421319.3 | P14: 0 | Q14: 0 | R14: 0 | S14: 0
A15: 8 | F15: 1006 | H15: Банкноти та монети на зберіганні в інкасаторській компанії | I15: А | J15: 0 | K15: 0 | L15: 0 | M15: 0 | O15: 0 | P15: 0 | Q15: 0 | R15: 0 | S15: 0
A16: 9 | F16: 1007 | H16: Банкноти та монети в дорозі | I16: А | J16: 87343053 | K16: 48587812 | L16: 38755241 | M16: 88657287 | O16: 48620577 | P16: 40036710 | Q16: 2501103.5 | R16: 635549.67 | S16: 1865553.8
A17: 10 | F17: Група 100 - Усього | J17: 2.0584898e+08 | K17: 1.1951637e+08 | L17: 86332608 | M17: 2.076272e+08 | O17: 1.200211e+08 | P17: 87606106 | Q17: 13166192 | R17: 7248419.7 | S17: 5917772.6
A18: 11 | D18: 101 | F18: 1011 | H18: Дорожні чеки в касі банку | I18: А | J18: 0 | K18: 0 | L18: 0 | M18: 0 | O18: 0 | P18: 0 | Q18: 0 | R18: 0 | S18: 0
A19: 12 | F19: 1012 | H19: Дорожні чеки в касі відділень банку | I19: А | J19: 0 | K19: 0 | L19: 0 | M19: 0 | O19: 0 | P19: 0 | Q19: 0 | R19: 0 | S19: 0
A20: 13 | F20: Група 101 - Усього | J20: 0 | K20: 0 | L20: 0 | M20: 0 | O20: 0 | P20: 0 | Q20: 0 | R20: 0 | S20: 0
A21: 14 | D21: 109 | F21: 1090 | H21: Резерви за готівковими коштами, наявність яких є непідтвердженою | I21: П | J21: 77440.92 | K21: 77440.92 | L21: 0 | M21: 54298.72 | O21: 54298.72 | P21: 0 | Q21: -54298.72 | R21: -54298.72 | S21: 0
A22: 15 | F22: Група 109 - Усього | J22: 77440.92 | K22: 77440.92 | L22: 0 | M22: 54298.72 | O22: 54298.72 | P22: 0 | Q22: -54298.72 | R22: -54298.72 | S22: 0
A23: 16 | D23: Розділ 10 - Усього | J23: 2.0592642e+08 | K23: 1.1959381e+08 | L23: 86332608 | M23: 2.076815e+08 | O23: 1.200754e+08 | P23: 87606106 | Q23: 13111894 | R23: 7194121 | S23: 5917772.6
A24: 17 | C24: 11 | D24: 110 | F24: 1101 | H24: Банківські метали в банку | I24: А | J24: 0 | K24: 0 | L24: 0 | M24: 0 | O24: 0 | P24: 0 | Q24: 0 | R24: 0 | S24: 0
A25: 18 | F25: 1102 | H25: Банківські метали у відділенні банку | I25: А | J25: 0 | K25: 0 | L25: 0 | M25: 0 | O25: 0 | P25: 0 | Q25: 0 | R25: 0 | S25: 0
A26: 19 | F26: 1107 | H26: Банківські метали в дорозі | I26: А | J26: 0 | K26: 0 | L26: 0 | M26: 0 | O26: 0 | P26: 0 | Q26: 0 | R26: 0 | S26: 0
A27: 20 | F27: Група 110 - Усього | J27: 0 | K27: 0 | L27: 0 | M27: 0 | O27: 0 | P27: 0 | Q27: 0 | R27: 0 | S27: 0
A28: 21 | D28: 119 | F28: 1190 | H28: Резерви за банківськими металами, наявність яких є непідтвердженою | I28: П | J28: 0 | K28: 0 | L28: 0 | M28: 0 | O28: 0 | P28: 0 | Q28: 0 | R28: 0 | S28: 0
A29: 22 | F29: Група 119 - Усього | J29: 0 | K29: 0 | L29: 0 | M29: 0 | O29: 0 | P29: 0 | Q29: 0 | R29: 0 | S29: 0
A30: 23 | D30: Розділ 11 - Усього | J30: 0 | K30: 0 | L30: 0 | M30: 0 | O30: 0 | P30: 0 | Q30: 0 | R30: 0 | S30: 0
A31: 24 | C31: 12 | D31: 120 | F31: 1200 | H31: Кореспондентський рахунок банку в Національному банку України | I31: А | J31: 8.0173461e+08 | K31: 8.0173461e+08 | L31: 0 | M31: 8.0090905e+08 | O31: 8.0090905e+08 | P31: 0 | Q31: 17682726 | R31: 17682726 | S31: 0
A32: 25 | F32: 1202 | H32: Кошти банків за рахунками умовного зберігання (ескроу) у Національному банку України | I32: А | J32: 0 | K32: 0 | L32: 0 | M32: 0 | O32: 0 | P32: 0 | Q32: 0 | R32: 0 | S32: 0
A33: 26 | F33: 1205 | H33: Кошти банків для забезпечення виконання зобов’язань перед Національним банком України за кредитами, наданими банкам, та операціями своп процентної ставки | I33: А | J33: 0 | K33: 0 | L33: 0 | M33: 0 | O33: 0 | P33: 0 | Q33: 0 | R33: 0 | S33: 0
A34: 27 | F34: 1208 | H34: Нараховані доходи за коштами на вимогу в Національному банку України | I34: А | J34: 0 | K34: 0 | L34: 0 | M34: 0 | O34: 0 | P34: 0 | Q34: 0 | R34: 0 | S34: 0
A35: 28 | F35: Група 120 - Усього | J35: 8.0173461e+08 | K35: 8.0173461e+08 | L35: 0 | M35: 8.0090905e+08 | O35: 8.0090905e+08 | P35: 0 | Q35: 17682726 | R35: 17682726 | S35: 0
A36: 29 | D36: Розділ 12 - Усього | J36: 8.0173461e+08 | K36: 8.0173461e+08 | L36: 0 | M36: 8.0090905e+08 | O36: 8.0090905e+08 | P36: 0 | Q36: 17682726 | R36: 17682726 | S36: 0
A37: 30 | C37: 14 | D37: 140 | F37: 1400 | H37: Облігації внутрішньої державної позики, що рефінансуються Національним банком України, які обліковуються за справедливою вартістю через прибутки/збитки | I37: А | J37: 413467.08 | K37: 366890 | L37: 46577.079 | M37: 517980.06 | O37: 499053 | P37: 18927.062 | Q37: 5267480.5 | R37: 5194758 | S37: 72722.55
A38: 31 | F38: 1405 | H38: Переоцінка боргових цінних паперів, що рефінансуються Національним банком України, які обліковуються за справедливою вартістю через прибутки/збитки | I38: А | J38: 2488491.7 | K38: 2454098 | L38: 34393.697 | M38: 2466917.9 | O38: 2431662.6 | P38: 35255.313 | Q38: 77252.277 | R38: 77252.277 | S38: 0
A39: 32 | I39: П | J39: 0 | K39: 0 | L39: 0 | M39: 0 | O39: 0 | P39: 0 | Q39: -47162.485 | R39: -44734.309 | S39: -2428.1759
A40: 33 | F40: 1406 | H40: Неамортизована премія/дисконт за борговими цінними паперами, що рефінансуються Національним банком України, які обліковуються за справедливою вартістю через прибутки/збитки | I40: А | J40: 15347.928 | K40: 15146.59 | L40: 201.33835 | M40: 13684.611 | O40: 13415.967 | P40: 268.644 | Q40: 108169.76 | R40: 108009.65 | S40: 160.11092
...

Sheet  43АТ "АЛЬТБАНК" 
A1: Зміст
B2: Оборотно-сальдовий баланс банку АТ "АЛЬТБАНК" за станом на 01.12.2025
B3: (тис грн)
A4: Номер з/п | B4: Клас/ розділ/ група/ рахунок | I4: Актив/ пасив | J4: Обороти за місяць | Q4: Сальдо
J5: дебет | M5: кредит | Q5: усього | R5: НВ | S5: ІВ
B6: номер | F6: назва | J6: усього | K6: НВ | L6: ІВ | M6: усього | O6: НВ | P6: ІВ
A7: 1 | B7: 2 | F7: 3 | I7: 4 | J7: 5 | K7: 6 | L7: 7 | M7: 8 | O7: 9 | P7: 10 | Q7: 11 | R7: 12 | S7: 13
A8: 1 | B8: Балансові рахунки
A9: 2 | B9: Активи
A10: 3 | B10: Класи 1 - 4
A11: 4 | B11: Клас 1 | C11: 10 | D11: 100 | F11: 1001 | H11: Банкноти та монети в касі банку | I11: А | J11: 28154.385 | K11: 21779.658 | L11: 6374.7271 | M11: 29506.086 | O11: 20971.329 | P11: 8534.7572 | Q11: 9920.2462 | R11: 2915.2424 | S11: 7005.0038
A12: 5 | F12: 1002 | H12: Банкноти та монети в касі відділень банку | I12: А | J12: 30435.051 | K12: 21849.263 | L12: 8585.788 | M12: 37683.004 | O12: 23400.829 | P12: 14282.174 | Q12: 19994.412 | R12: 5674.948 | S12: 14319.464
A13: 6 | F13: 1004 | H13: Банкноти та монети в банкоматах | I13: А | J13: 17285.86 | K13: 17285.86 | L13: 0 | M13: 16009.91 | O13: 16009.91 | P13: 0 | Q13: 6850.8 | R13: 6850.8 | S13: 0
A14: 7 | F14: 1005 | H14: Банкноти та монети, інкасовані до перерахування | I14: А | J14: 0 | K14: 0 | L14: 0 | M14: 0 | O14: 0 | P14: 0 | Q14: 0 | R14: 0 | S14: 0
A15: 8 | F15: 1006 | H15: Банкноти та монети на зберіганні в інкасаторській компанії | I15: А | J15: 0 | K15: 0 | L15: 0 | M15: 0 | O15: 0 | P15: 0 | Q15: 0 | R15: 0 | S15: 0
A16: 9 | F16: 1007 | H16: Банкноти та монети в дорозі | I16: А | J16: 16839.968 | K16: 12298.06 | L16: 4541.9076 | M16: 16839.968 | O16: 12298.06 | P16: 4541.9076 | Q16: 0 | R16: 0 | S16: 0
A17: 10 | F17: Група 100 - Усього | J17: 92715.264 | K17: 73212.841 | L17: 19502.423 | M17: 100038.97 | O17: 72680.129 | P17: 27358.839 | Q17: 36765.458 | R17: 15440.99 | S17: 21324.467
A18: 11 | D18: 101 | F18: 1011 | H18: Дорожні чеки в касі банку | I18: А | J18: 0 | K18: 0 | L18: 0 | M18: 0 | O18: 0 | P18: 0 | Q18: 0 | R18: 0 | S18: 0
A19: 12 | F19: 1012 | H19: Дорожні чеки в касі відділень банку | I19: А | J19: 0 | K19: 0 | L19: 0 | M19: 0 | O19: 0 | P19: 0 | Q19: 0 | R19: 0 | S19: 0
A20: 13 | F20: Група 101 - Усього | J20: 0 | K20: 0 | L20: 0 | M20: 0 | O20: 0 | P20: 0 | Q20: 0 | R20: 0 | S20: 0
A21: 14 | D21: 109 | F21: 1090 | H21: Резерви за готівковими коштами, наявність яких є непідтвердженою | I21: П | J21: 0 | K21: 0 | L21: 0 | M21: 0 | O21: 0 | P21: 0 | Q21: 0 | R21: 0 | S21: 0
A22: 15 | F22: Група 109 - Усього | J22: 0 | K22: 0 | L22: 0 | M22: 0 | O22: 0 | P22: 0 | Q22: 0 | R22: 0 | S22: 0
A23: 16 | D23: Розділ 10 - Усього | J23: 92715.264 | K23: 73212.841 | L23: 19502.423 | M23: 100038.97 | O23: 72680.129 | P23: 27358.839 | Q23: 36765.458 | R23: 15440.99 | S23: 21324.467
A24: 17 | C24: 11 | D24: 110 | F24: 1101 | H24: Банківські метали в банку | I24: А | J24: 0 | K24: 0 | L24: 0 | M24: 0 | O24: 0 | P24: 0 | Q24: 0 | R24: 0 | S24: 0
A25: 18 | F25: 1102 | H25: Банківські метали у відділенні банку | I25: А | J25: 0 | K25: 0 | L25: 0 | M25: 0 | O25: 0 | P25: 0 | Q25: 0 | R25: 0 | S25: 0
A26: 19 | F26: 1107 | H26: Банківські метали в дорозі | I26: А | J26: 0 | K26: 0 | L26: 0 | M26: 0 | O26: 0 | P26: 0 | Q26: 0 | R26: 0 | S26: 0
A27: 20 | F27: Група 110 - Усього | J27: 0 | K27: 0 | L27: 0 | M27: 0 | O27: 0 | P27: 0 | Q27: 0 | R27: 0 | S27: 0
A28: 21 | D28: 119 | F28: 1190 | H28: Резерви за банківськими металами, наявність яких є непідтвердженою | I28: П | J28: 0 | K28: 0 | L28: 0 | M28: 0 | O28: 0 | P28: 0 | Q28: 0 | R28: 0 | S28: 0
A29: 22 | F29: Група 119 - Усього | J29: 0 | K29: 0 | L29: 0 | M29: 0 | O29: 0 | P29: 0 | Q29: 0 | R29: 0 | S29: 0
A30: 23 | D30: Розділ 11 - Усього | J30: 0 | K30: 0 | L30: 0 | M30: 0 | O30: 0 | P30: 0 | Q30: 0 | R30: 0 | S30: 0
A31: 24 | C31: 12 | D31: 120 | F31: 1200 | H31: Кореспондентський рахунок банку в Національному банку України | I31: А | J31: 6987129.7 | K31: 6987129.7 | L31: 0 | M31: 7053942.3 | O31: 7053942.3 | P31: 0 | Q31: 165603.41 | R31: 165603.41 | S31: 0
A32: 25 | F32: 1202 | H32: Кошти банків за рахунками умовного зберігання (ескроу) у Національному банку України | I32: А | J32: 0 | K32: 0 | L32: 0 | M32: 0 | O32: 0 | P32: 0 | Q32: 0 | R32: 0 | S32: 0
A33: 26 | F33: 1205 | H33: Кошти банків для забезпечення виконання зобов’язань перед Національним банком України за кредитами, наданими банкам, та операціями своп процентної ставки | I33: А | J33: 0 | K33: 0 | L33: 0 | M33: 0 | O33: 0 | P33: 0 | Q33: 0 | R33: 0 | S33: 0
A34: 27 | F34: 1208 | H34: Нараховані доходи за коштами на вимогу в Національному банку України | I34: А | J34: 0 | K34: 0 | L34: 0 | M34: 0 | O34: 0 | P34: 0 | Q34: 0 | R34: 0 | S34: 0
A35: 28 | F35: Група 120 - Усього | J35: 6987129.7 | K35: 6987129.7 | L35: 0 | M35: 7053942.3 | O35: 7053942.3 | P35: 0 | Q35: 165603.41 | R35: 165603.41 | S35: 0
A36: 29 | D36: Розділ 12 - Усього | J36: 6987129.7 | K36: 6987129.7 | L36: 0 | M36: 7053942.3 | O36: 7053942.3 | P36: 0 | Q36: 165603.41 | R36: 165603.41 | S36: 0
A37: 30 | C37: 14 | D37: 140 | F37: 1400 | H37: Облігації внутрішньої державної позики, що рефінансуються Національним банком України, які обліковуються за справедливою вартістю через прибутки/збитки | I37: А | J37: 0 | K37: 0 | L37: 0 | M37: 0 | O37: 0 | P37: 0 | Q37: 0 | R37: 0 | S37: 0
A38: 31 | F38: 1405 | H38: Переоцінка боргових цінних паперів, що рефінансуються Національним банком України, які обліковуються за справедливою вартістю через прибутки/збитки | I38: А | J38: 0 | K38: 0 | L38: 0 | M38: 0 | O38: 0 | P38: 0 | Q38: 0 | R38: 0 | S38: 0
A39: 32 | I39: П | J39: 0 | K39: 0 | L39: 0 | M39: 0 | O39: 0 | P39: 0 | Q39: 0 | R39: 0 | S39: 0
A40: 33 | F40: 1406 | H40: Неамортизована премія/дисконт за борговими цінними паперами, що рефінансуються Національним банком України, які обліковуються за справедливою вартістю через прибутки/збитки | I40: А | J40: 0 | K40: 0 | L40: 0 | M40: 0 | O40: 0 | P40: 0 | Q40: 0 | R40: 0 | S40: 0
...
